File: lab2/data/lab1Test3.csv
Time,Displacement,Force,Strain 1
(s),(mm),(kN),(%)
0,3.0109,0.0001,-0.0004
0.2,3.0226,0.0211,0.0062
0.4,3.0376,0.0288,0.0046
0.6,3.0526,0.0386,0.0021
0.8,3.0676,0.0421,0.0054
1,3.0825,0.0442,0.0057
1.2,3.0975,0.0466,0.0115
1.4,3.1126,0.0475,0.0071
1.6,3.1276,0.0482,0.0063
1.8,3.1425,0.0504,0.0045
2,3.1575,0.0521,0.0036
2.2,3.1726,0.0548,0.0027
2.4,3.1876,0.0565,0.0037
2.6,3.2025,0.0574,0.0053
2.8,3.2175,0.0581,0.0037
3,3.2325,0.0596,0.0031
3.2,3.2475,0.061,0.0018
3.4,3.2625,0.0633,0.0016
3.6,3.2776,0.0672,-0.0007
3.8,3.2926,0.0752,-0.0028
4,3.3075,0.084,-0.0052
4.2,3.3225,0.1151,-0.0062
4.4,3.3375,0.1558,-0.0055
4.6,3.3526,0.1975,-0.0056
4.8,3.3675,0.2265,-0.0056
5,3.3825,0.2483,-0.0058
5.2,3.3976,0.264,-0.006
5.4,3.4126,0.2765,-0.0058
5.6,3.4275,0.2874,-0.0071
5.8,3.4425,0.2968,-0.0073
6,3.4575,0.3042,-0.0072
6.2,3.4725,0.3107,-0.0074
6.4,3.4876,0.3184,-0.0082
6.6,3.5027,0.3252,-0.0079
6.8,3.5176,0.3335,-0.0081
7,3.5326,0.3428,-0.0085
7.2,3.5475,0.3534,-0.0086
7.4,3.5625,0.3653,-0.008
7.6,3.5775,0.3783,-0.0086
7.8,3.5926,0.3952,-0.0083
8,3.6076,0.4159,-0.0079
8.2,3.6226,0.4392,-0.0069
8.4,3.6375,0.4652,-0.0062
8.6,3.6526,0.4934,-0.0055
8.8,3.6675,0.5231,-0.0049
9,3.6825,0.5552,-0.0039
9.2,3.6975,0.5889,-0.0034
9.4,3.7126,0.6244,-0.002
9.6,3.7275,0.6603,-0.0008
9.8,3.7426,0.6976,0.0001
10,3.7575,0.7357,0.0011
10.2,3.7726,0.7749,0.0025
10.4,3.7875,0.8138,0.0033
10.6,3.8025,0.8538,0.0044
10.8,3.8175,0.894,0.006
11,3.8326,0.9352,0.0074
11.2,3.8475,0.9756,0.008
11.4,3.8625,1.0158,0.0094
11.6,3.8775,1.0558,0.0106
11.8,3.8926,1.0959,0.0115
12,3.9075,1.1357,0.0125
12.2,3.9225,1.176,0.014
12.4,3.9375,1.216,0.0153
12.6,3.9526,1.2568,0.0156
12.8,3.9675,1.297,0.0177
13,3.9825,1.338,0.019
13.2,3.9975,1.3795,0.0209
13.4,4.0126,1.422,0.0221
13.6,4.0275,1.4651,0.0235
13.8,4.0426,1.511,0.0245
14,4.0576,1.5592,0.0257
14.2,4.0726,1.6099,0.0272
14.4,4.0875,1.6611,0.0288
14.6,4.1025,1.7143,0.0303
14.8,4.1175,1.7686,0.0322
15,4.1325,1.8254,0.0339
15.2,4.1475,1.8822,0.0353
15.4,4.1625,1.9424,0.0364
15.6,4.1776,2.0032,0.039
15.8,4.1926,2.0658,0.0405
16,4.2074,2.1282,0.0421
16.2,4.2224,2.1931,0.044
16.4,4.2375,2.2585,0.0461
16.6,4.2525,2.3263,0.0483
16.8,4.2675,2.3946,0.05
17,4.2825,2.4657,0.0523
17.2,4.2976,2.5373,0.0547
17.4,4.3126,2.6104,0.0573
17.6,4.3275,2.6829,0.0604
17.8,4.3425,2.7589,0.0631
18,4.3575,2.8354,0.0653
18.2,4.3725,2.9142,0.0676
18.4,4.3875,2.9931,0.0704
18.6,4.4025,3.075,0.0724
18.8,4.4176,3.1569,0.0749
19,4.4325,3.2405,0.078
19.2,4.4475,3.3243,0.081
19.4,4.4625,3.4103,0.0832
19.6,4.4774,3.497,0.0861
19.8,4.4925,3.5871,0.0896
20,4.5076,3.6766,0.0926
20.2,4.5225,3.7684,0.0952
20.4,4.5375,3.8611,0.0984
20.6,4.5525,3.9551,0.1015
20.8,4.5675,4.0496,0.1044
21,4.5825,4.1463,0.1078
21.2,4.5976,4.2433,0.1105
21.4,4.6125,4.3417,0.114
21.6,4.6276,4.4411,0.1169
21.8,4.6425,4.5404,0.1204
22,4.6575,4.6416,0.1254
22.2,4.6724,4.7424,0.1286
22.4,4.6875,4.8447,0.1313
22.6,4.7024,4.9474,0.135
22.8,4.7176,5.0531,0.1385
23,4.7325,5.157,0.1415
23.2,4.7476,5.2634,0.1452
23.4,4.7625,5.3697,0.1485
23.6,4.7776,5.478,0.1517
23.8,4.7924,5.5854,0.1555
24,4.8075,5.6949,0.1589
24.2,4.8225,5.8046,0.1627
24.4,4.8376,5.9167,0.1662
24.6,4.8525,6.0271,0.1703
24.8,4.8676,6.1391,0.1735
25,4.8825,6.2504,0.1769
25.2,4.8976,6.3648,0.181
25.4,4.9124,6.4763,0.1847
25.6,4.9275,6.592,0.1875
25.8,4.9425,6.7064,0.1915
26,4.9576,6.823,0.1954
26.2,4.9724,6.9379,0.1988
26.4,4.9876,7.0553,0.2022
26.6,5.0025,7.171,0.2065
26.8,5.0175,7.2896,0.2102
27,5.0324,7.4062,0.2135
27.2,5.0475,7.525,0.2176
27.4,5.0625,7.6446,0.2211
27.6,5.0776,7.765,0.2247
27.8,5.0925,7.8839,0.2281
28,5.1076,8.0053,0.2332
28.2,5.1225,8.1247,0.2414
28.4,5.1374,8.2457,0.2457
28.6,5.1524,8.3668,0.247
28.8,5.1676,8.4902,0.2547
29,5.1825,8.6113,0.258
29.2,5.1976,8.7359,0.2638
29.4,5.2125,8.8566,0.2687
29.6,5.2275,8.9803,0.2718
29.8,5.2425,9.1039,0.2757
30,5.2575,9.2282,0.2801
30.2,5.2724,9.3513,0.2842
30.4,5.2875,9.4791,0.2881
30.6,5.3026,9.6046,0.292
30.8,5.3175,9.7292,0.2962
31,5.3324,9.8538,0.3005
31.2,5.3476,9.9821,0.3044
31.4,5.3624,10.1059,0.3095
31.6,5.3775,10.2341,0.3129
31.8,5.3924,10.3596,0.3167
32,5.4076,10.4879,0.3211
32.2,5.4225,10.6147,0.3265
32.4,5.4376,10.7423,0.3305
32.6,5.4524,10.8668,0.3344
32.8,5.4675,10.9966,0.3393
33,5.4825,11.124,0.3434
33.2,5.4975,11.2528,0.3474
33.4,5.5125,11.3809,0.3519
33.6,5.5276,11.5108,0.3564
33.8,5.5425,11.6385,0.3605
34,5.5575,11.7677,0.3647
34.2,5.5724,11.8948,0.3718
34.4,5.5875,12.0242,0.3766
34.6,5.6025,12.153,0.3796
34.8,5.6175,12.283,0.3847
35,5.6324,12.4102,0.3891
35.2,5.6476,12.5417,0.393
35.4,5.6626,12.6694,0.3972
35.6,5.6775,12.7967,0.4025
35.8,5.6924,12.9242,0.4075
36,5.7076,13.0539,0.4117
36.2,5.7225,13.1821,0.4169
36.4,5.7375,13.3105,0.4214
36.6,5.7525,13.4379,0.4257
36.8,5.7675,13.5658,0.4306
37,5.7826,13.6943,0.4358
37.2,5.7975,13.8194,0.4421
37.4,5.8125,13.9452,0.4475
37.6,5.8275,14.0725,0.4523
37.8,5.8426,14.1988,0.4578
38,5.8575,14.3223,0.4618
38.2,5.8725,14.4466,0.4689
38.4,5.8875,14.5688,0.4743
38.6,5.9025,14.6908,0.4787
38.8,5.9174,14.8107,0.4839
39,5.9325,14.9313,0.4894
39.2,5.9475,15.0501,0.4946
39.4,5.9626,15.1693,0.4991
39.6,5.9775,15.2845,0.5051
39.8,5.9925,15.4004,0.5104
40,6.0075,15.5138,0.5156
40.2,6.0226,15.6258,0.5214
40.4,6.0374,15.7343,0.5274
40.6,6.0525,15.8443,0.5329
40.8,6.0675,15.9502,0.5392
41,6.0826,16.0564,0.5464
41.2,6.0975,16.1568,0.5531
41.4,6.1126,16.2575,0.5595
41.6,6.1275,16.3534,0.5669
41.8,6.1426,16.4486,0.5749
42,6.1575,16.537,0.5825
42.2,6.1725,16.6253,0.5915
42.4,6.1876,16.7105,0.6013
42.6,6.2027,16.7899,0.6104
42.8,6.2174,16.8614,0.6201
43,6.2326,16.9318,0.6306
43.2,6.2476,16.9916,0.642
43.4,6.2625,17.0453,0.6539
43.6,6.2775,17.0901,0.667
43.8,6.2926,17.1283,0.6816
44,6.3075,17.1605,0.6981
44.2,6.3226,17.1892,0.719
44.4,6.3375,17.2112,0.7371
44.6,6.3525,17.2351,0.7553
44.8,6.3675,17.255,0.773
45,6.3826,17.2755,0.7914
45.2,6.3974,17.2923,0.8123
45.4,6.4126,17.3124,0.8357
45.6,6.4276,17.3291,0.8552
45.8,6.4426,17.3467,0.8751
46,6.4575,17.3611,0.8951
46.2,6.4726,17.3777,0.9154
46.4,6.4875,17.3926,0.9345
46.6,6.5026,17.4092,0.9549
46.8,6.5175,17.422,0.974
47,6.5325,17.4384,0.9928
47.2,6.5476,17.4544,1.0127
47.4,6.5627,17.4676,1.0335
47.6,6.5774,17.4795,1.0526
47.8,6.5925,17.4961,1.0733
48,6.6076,17.5086,1.0925
48.2,6.6225,17.5233,1.1114
48.4,6.6375,17.536,1.1297
48.6,6.6526,17.5504,1.1488
48.8,6.6676,17.565,1.1677
49,6.6826,17.5782,1.1856
49.2,6.6975,17.5895,1.2043
49.4,6.7125,17.6039,1.2226
49.6,6.7276,17.6177,1.2406
49.8,6.7426,17.6296,1.258
50,6.7575,17.6425,1.2761
50.2,6.7726,17.6566,1.2946
50.4,6.7876,17.6693,1.3116
50.6,6.8025,17.6806,1.3291
50.8,6.8175,17.6928,1.347
51,6.8325,17.7059,1.365
51.2,6.8476,17.7201,1.3827
51.4,6.8626,17.7321,1.4005
51.6,6.8776,17.744,1.4176
51.8,6.8925,17.7574,1.4341
52,6.9076,17.7707,1.4514
52.2,6.9225,17.7803,1.4701
52.4,6.9375,17.7939,1.4865
52.6,6.9525,17.806,1.5036
52.8,6.9676,17.8196,1.5218
53,6.9825,17.8311,1.5402
53.2,6.9976,17.8436,1.5574
53.4,7.0125,17.854,1.5746
53.6,7.0276,17.8692,1.5931
53.8,7.0425,17.8778,1.6107
54,7.0575,17.8902,1.6279
54.2,7.0725,17.9021,1.6465
54.4,7.0877,17.9164,1.6637
54.6,7.1025,17.9262,1.6815
54.8,7.1176,17.939,1.6999
55,7.1325,17.9493,1.7183
55.2,7.1476,17.9632,1.7357
55.4,7.1625,17.9728,1.7533
55.6,7.1776,17.9852,1.7721
55.8,7.1925,17.9956,1.79
56,7.2076,18.0105,1.808
56.2,7.2226,18.0196,1.8263
56.4,7.2376,18.0307,1.845
56.6,7.2525,18.0416,1.8632
56.8,7.2677,18.0547,1.881
57,7.2824,18.0615,1.8995
57.2,7.2976,18.0762,1.9184
57.4,7.3126,18.0863,1.9368
57.6,7.3276,18.0996,1.9551
57.8,7.3425,18.1083,1.9736
58,7.3576,18.1205,1.9925
58.2,7.3725,18.1294,2.0102
58.4,7.3876,18.1429,2.0286
58.6,7.4025,18.1511,2.0464
58.8,7.4175,18.1634,2.0636
59,7.4326,18.1755,2.0817
59.2,7.4477,18.1873,2.1003
59.4,7.4625,18.1942,2.1179
59.6,7.4775,18.2066,2.136
59.8,7.4925,18.2164,2.1535
60,7.5075,18.2276,2.1709
60.2,7.5224,18.2368,2.1883
60.4,7.5377,18.2494,2.2058
60.6,7.5525,18.2579,2.2246
60.8,7.5676,18.271,2.242
61,7.5825,18.2782,2.2588
61.2,7.5975,18.2897,2.2761
61.4,7.6125,18.2992,2.295
61.6,7.6276,18.3107,2.3124
61.8,7.6425,18.3193,2.3296
62,7.6576,18.3317,2.3482
62.2,7.6726,18.3409,2.366
62.4,7.6875,18.3519,2.3829
62.6,7.7024,18.3601,2.401
62.8,7.7176,18.3708,2.4183
63,7.7325,18.38,2.4357
63.2,7.7475,18.3918,2.453
63.4,7.7626,18.3997,2.4703
63.6,7.7776,18.4108,2.4882
63.8,7.7926,18.4207,2.505
64,7.8076,18.4303,2.5215
64.2,7.8224,18.4375,2.5401
64.4,7.8375,18.4486,2.5577
64.6,7.8526,18.4579,2.5754
64.8,7.8675,18.4682,2.5935
65,7.8825,18.478,2.612
65.2,7.8975,18.4874,2.6286
65.4,7.9125,18.4975,2.6458
65.6,7.9275,18.5072,2.664
65.8,7.9425,18.5142,2.6818
66,7.9575,18.5228,2.699
66.2,7.9726,18.5345,2.7164
66.4,7.9875,18.5433,2.734
66.6,8.0026,18.5519,2.751
66.8,8.0176,18.562,2.7687
67,8.0326,18.571,2.7868
67.2,8.0474,18.5783,2.8037
67.4,8.0625,18.5887,2.8214
67.6,8.0775,18.5961,2.8395
67.8,8.0926,18.6071,2.8578
68,8.1075,18.6156,2.8748
68.2,8.1226,18.6247,2.8923
68.4,8.1375,18.6318,2.9101
68.6,8.1526,18.6435,2.9286
68.8,8.1674,18.6489,2.9457
69,8.1825,18.6597,2.9642
69.2,8.1975,18.6673,2.9822
69.4,8.2127,18.6772,2.9998
69.6,8.2274,18.6838,3.0166
69.8,8.2426,18.695,3.0344
70,8.2575,18.7012,3.0525
70.2,8.2726,18.7102,3.0711
70.4,8.2874,18.7175,3.0886
70.6,8.3026,18.7278,3.1067
70.8,8.3175,18.734,3.1259
71,8.3327,18.7459,3.1433
71.2,8.3474,18.7507,3.1611
71.4,8.3626,18.7613,3.1794
71.6,8.3775,18.768,3.196
71.8,8.3926,18.7773,3.2137
72,8.4074,18.7826,3.2322
72.2,8.4226,18.7934,3.2498
72.4,8.4375,18.7996,3.2676
72.6,8.4526,18.8105,3.2862
72.8,8.4675,18.816,3.3039
73,8.4827,18.8254,3.3213
73.2,8.4974,18.8308,3.3381
73.4,8.5126,18.8418,3.3562
73.6,8.5274,18.8458,3.3734
73.8,8.5426,18.8565,3.3906
74,8.5576,18.863,3.4074
74.2,8.5727,18.8721,3.4252
74.4,8.5874,18.8766,3.4423
74.6,8.6026,18.8872,3.4595
74.8,8.6175,18.8923,3.4777
75,8.6325,18.9024,3.4966
75.2,8.6474,18.9076,3.5138
75.4,8.6626,18.9172,3.5316
75.6,8.6775,18.9235,3.5498
75.8,8.6926,18.933,3.5685
76,8.7074,18.9361,3.5872
76.2,8.7226,18.9467,3.605
76.4,8.7375,18.9514,3.6225
76.6,8.7526,18.9601,3.6394
76.8,8.7674,18.966,3.6574
77,8.7827,18.9762,3.6754
77.2,8.7975,18.98,3.6939
77.4,8.8126,18.99,3.711
77.6,8.8274,18.994,3.7282
77.8,8.8426,19.0023,3.7463
78,8.8575,19.0088,3.7633
78.2,8.8726,19.0169,3.7807
78.4,8.8874,19.0214,3.7994
78.6,8.9026,19.0326,3.8166
78.8,8.9176,19.0382,3.8335
79,8.9326,19.0445,3.8507
79.2,8.9474,19.0491,3.8704
79.4,8.9626,19.058,3.8881
79.6,8.9775,19.0626,3.9051
79.8,8.9926,19.0719,3.9229
80,9.0076,19.077,3.9424
80.2,9.0226,19.0837,3.9627
80.4,9.0376,19.0909,3.9803
80.6,9.0526,19.0976,3.9979
80.8,9.0674,19.1011,4.0154
81,9.0825,19.11,4.0328
81.2,9.0976,19.117,4.0515
81.4,9.1125,19.1229,4.0702
81.6,9.1275,19.13,4.0875
81.8,9.1426,19.1368,4.1053
82,9.1576,19.1417,4.1246
82.2,9.1725,19.1475,4.1424
82.4,9.1876,19.1542,4.1606
82.6,9.2025,19.16,4.1785
82.8,9.2176,19.1678,4.1963
83,9.2326,19.1727,4.2142
83.2,9.2475,19.1782,4.2314
83.4,9.2626,19.1852,4.2491
83.6,9.2777,19.1915,4.2664
83.8,9.2924,19.1942,4.2835
84,9.3075,19.2021,4.3016
84.2,9.3226,19.2081,4.3201
84.4,9.3376,19.215,4.338
84.6,9.3525,19.2207,4.3556
84.8,9.3676,19.2273,4.3739
85,9.3825,19.2319,4.3934
85.2,9.3976,19.2393,4.4154
85.4,9.4125,19.2428,4.4342
85.6,9.4275,19.2481,4.4525
85.8,9.4425,19.2547,4.4713
86,9.4577,19.2622,4.4889
86.2,9.4725,19.2653,4.5079
86.4,9.4876,19.2731,4.5266
86.6,9.5026,19.2764,4.5455
86.8,9.5176,19.2826,4.5647
87,9.5325,19.286,4.5842
87.2,9.5476,19.2933,4.6025
87.4,9.5626,19.2987,4.6204
87.6,9.5777,19.3057,4.6398
87.8,9.5925,19.3089,4.6592
88,9.6075,19.3148,4.6771
88.2,9.6225,19.3204,4.6955
88.4,9.6376,19.3264,4.7149
88.6,9.6524,19.329,4.7333
88.8,9.6676,19.3362,4.7514
89,9.6826,19.3411,4.7696
89.2,9.6976,19.3468,4.7879
89.4,9.7125,19.3503,4.806
89.6,9.7276,19.3562,4.8248
89.8,9.7425,19.3606,4.8426
90,9.7576,19.3674,4.8612
90.2,9.7725,19.3691,4.8791
90.4,9.7876,19.3761,4.8973
90.6,9.8026,19.3821,4.916
90.8,9.8177,19.3872,4.9338
91,9.8324,19.3891,4.9514
91.2,9.8475,19.3959,4.9697
91.4,9.8625,19.4001,4.9888
91.6,9.8775,19.4057,5.0086
91.8,9.8925,19.4093,5.0271
92,9.9076,19.4152,5.0472
92.2,9.9225,19.42,5.0659
92.4,9.9376,19.4258,5.0846
92.6,9.9525,19.427,5.1061
92.8,9.9674,19.4324,5.1242
93,9.9825,19.4378,5.1443
93.2,9.9976,19.4421,5.1644
93.4,10.0124,19.4454,5.1841
93.6,10.0276,19.4523,5.2024
93.8,10.0426,19.4564,5.2199
94,10.0575,19.4602,5.239
94.2,10.0725,19.4641,5.26
94.4,10.0875,19.4686,5.2779
94.6,10.1025,19.4736,5.2959
94.8,10.1176,19.4795,5.3153
95,10.1326,19.4819,5.333
95.2,10.1475,19.4862,5.351
95.4,10.1626,19.4923,5.3696
95.6,10.1775,19.4941,5.3915
95.8,10.1924,19.4981,5.4099
96,10.2075,19.5027,5.4281
96.2,10.2226,19.5075,5.4478
96.4,10.2375,19.5117,5.4672
96.6,10.2526,19.5163,5.486
96.8,10.2676,19.5192,5.5066
97,10.2826,19.5248,5.526
97.2,10.2975,19.5278,5.5439
97.4,10.3126,19.5316,5.5619
97.6,10.3274,19.5345,5.5806
97.8,10.3427,19.5418,5.5985
98,10.3576,19.5435,5.6168
98.2,10.3725,19.5484,5.6346
98.4,10.3876,19.5516,5.6548
98.6,10.4026,19.5558,5.6727
98.8,10.4174,19.5574,5.6913
99,10.4325,19.5626,5.7099
99.2,10.4475,19.5654,5.7285
99.4,10.4626,19.5725,5.7458
99.6,10.4776,19.5738,5.765
99.8,10.4926,19.578,5.7866
100,10.5075,19.5806,5.8042
100.2,10.5227,19.5869,5.8227
100.4,10.5375,19.5863,5.8424
100.6,10.5525,19.5931,5.8625
100.8,10.5675,19.5959,5.8804
101,10.5827,19.6021,5.9016
101.2,10.5975,19.6032,5.9214
101.4,10.6127,19.6086,5.9402
101.6,10.6275,19.6088,5.959
101.8,10.6425,19.614,5.9773
102,10.6575,19.6166,5.9978
102.2,10.6726,19.6194,6.0163
102.4,10.6875,19.6235,6.035
102.6,10.7027,19.6288,6.0536
102.8,10.7175,19.6288,6.0728
103,10.7325,19.6344,6.0927
103.2,10.7475,19.6364,6.1125
103.4,10.7626,19.641,6.132
103.6,10.7774,19.6418,6.1514
103.8,10.7927,19.6479,6.1704
104,10.8075,19.6488,6.1892
104.2,10.8226,19.6552,6.2084
104.4,10.8375,19.6554,6.2272
104.6,10.8526,19.6594,6.2463
104.8,10.8675,19.6615,6.2672
105,10.8826,19.6666,6.2867
105.2,10.8974,19.6666,6.3071
105.4,10.9126,19.6726,6.3269
105.6,10.9276,19.6749,6.3467
105.8,10.9426,19.678,6.3658
106,10.9574,19.679,6.3846
106.2,10.9726,19.6837,6.4048
106.4,10.9874,19.6844,6.4244
106.6,11.0025,19.6895,6.4435
106.8,11.0175,19.6915,6.4634
107,11.0326,19.6954,6.4838
107.2,11.0476,19.6988,6.5037
107.4,11.0627,19.7025,6.5233
107.6,11.0774,19.701,6.5433
107.8,11.0925,19.7063,6.5639
108,11.1076,19.7085,6.5831
108.2,11.1225,19.7109,6.6025
108.4,11.1375,19.7133,6.6222
108.6,11.1527,19.7178,6.6419
108.8,11.1676,19.7188,6.6609
109,11.1825,19.7222,6.6809
109.2,11.1975,19.7234,6.7021
109.4,11.2125,19.7257,6.7218
109.6,11.2275,19.7296,6.742
109.8,11.2426,19.7326,6.7624
110,11.2575,19.7343,6.782
110.2,11.2726,19.7386,6.8025
110.4,11.2876,19.7409,6.8225
110.6,11.3025,19.7425,6.8428
110.8,11.3175,19.7452,6.8632
111,11.3326,19.7471,6.8832
111.2,11.3475,19.7495,6.9044
111.4,11.3625,19.752,6.9247
111.6,11.3776,19.755,6.9446
111.8,11.3925,19.7563,6.9644
112,11.4076,19.7604,6.9846
112.2,11.4225,19.7607,7.0041
112.4,11.4375,19.7627,7.0231
112.6,11.4524,19.7641,7.0437
112.8,11.4677,19.7692,7.0644
113,11.4825,19.7692,7.084
113.2,11.4975,19.7725,7.1039
113.4,11.5126,19.7749,7.1259
113.6,11.5275,19.7779,7.1463
113.8,11.5424,19.7781,7.1661
114,11.5576,19.7825,7.1861
114.2,11.5724,19.7832,7.207
114.4,11.5877,19.7891,7.2278
114.6,11.6025,19.787,7.2484
114.8,11.6175,19.7899,7.269
115,11.6325,19.7917,7.2895
115.2,11.6477,19.7947,7.3123
115.4,11.6624,19.7939,7.3333
115.6,11.6776,19.7986,7.3546
115.8,11.6925,19.7984,7.3748
116,11.7076,19.8033,7.3947
116.2,11.7225,19.803,7.4155
116.4,11.7377,19.8066,7.4379
116.6,11.7524,19.8064,7.4597
116.8,11.7676,19.8111,7.4817
117,11.7824,19.809,7.5043
117.2,11.7976,19.8143,7.5251
117.4,11.8125,19.8153,7.546
117.6,11.8277,19.8179,7.5664
117.8,11.8424,19.8171,7.587
118,11.8577,19.8225,7.6071
118.2,11.8725,19.8202,7.6273
118.4,11.8875,19.8238,7.648
118.6,11.9024,19.8236,7.6681
118.8,11.9177,19.8274,7.6886
119,11.9325,19.8275,7.7092
119.2,11.9477,19.8321,7.7309
119.4,11.9624,19.8294,7.7512
119.6,11.9775,19.8339,7.7713
119.8,11.9925,19.8337,7.7923
120,12.0076,19.8366,7.8129
120.2,12.0224,19.8367,7.8323
120.4,12.0376,19.8413,7.8542
120.6,12.0525,19.8404,7.8746
120.8,12.0676,19.8448,7.8951
121,12.0824,19.8431,7.9158
121.2,12.0976,19.8467,7.9372
121.4,12.1125,19.8459,7.9579
121.6,12.1277,19.8505,7.9792
121.8,12.1425,19.8475,8.0002
122,12.1576,19.8515,8.0232
122.2,12.1726,19.8527,8.0438
122.4,12.1876,19.8548,8.0648
122.6,12.2024,19.8532,8.0855
122.8,12.2176,19.8573,8.1073
123,12.2325,19.8566,8.1275
123.2,12.2475,19.8598,8.1491
123.4,12.2625,19.8598,8.1719
123.6,12.2777,19.8633,8.1934
123.8,12.2925,19.8629,8.2145
124,12.3076,19.8648,8.2368
124.2,12.3224,19.8634,8.2596
124.4,12.3375,19.8665,8.2832
124.6,12.3526,19.8677,8.3058
124.8,12.3676,19.8694,8.3284
125,12.3825,19.8684,8.3501
125.2,12.3976,19.8722,8.3715
125.4,12.4126,19.8721,8.3938
125.6,12.4275,19.8727,8.4157
125.8,12.4425,19.8726,8.4374
126,12.4575,19.8742,8.4591
126.2,12.4725,19.8758,8.4818
126.4,12.4876,19.8774,8.5048
126.6,12.5026,19.8782,8.5271
126.8,12.5175,19.8794,8.5506
127,12.5326,19.8807,8.5734
127.2,12.5475,19.8804,8.595
127.4,12.5625,19.8805,8.6173
127.6,12.5775,19.8811,8.64
127.8,12.5926,19.8828,8.6617
128,12.6075,19.8844,8.684
128.2,12.6226,19.8859,8.7073
128.4,12.6376,19.885,8.7306
128.6,12.6526,19.8871,8.7524
128.8,12.6676,19.8868,8.7754
129,12.6825,19.8863,8.7998
129.2,12.6975,19.8879,8.8227
129.4,12.7127,19.8905,8.8454
129.6,12.7275,19.8888,8.87
129.8,12.7426,19.8915,8.8933
130,12.7576,19.8909,8.9158
130.2,12.7726,19.8916,8.9399
130.4,12.7874,19.8894,8.9634
130.6,12.8026,19.8924,8.987
130.8,12.8175,19.8919,9.0092
131,12.8326,19.8935,9.0339
131.2,12.8476,19.8923,9.0569
131.4,12.8626,19.8928,9.0801
131.6,12.8775,19.8939,9.1045
131.8,12.8927,19.8951,9.1287
132,12.9075,19.8919,9.152
132.2,12.9225,19.8935,9.1752
132.4,12.9376,19.8946,9.1997
132.6,12.9527,19.8963,9.2235
132.8,12.9675,19.8945,9.2469
133,12.9826,19.8961,9.2713
133.2,12.9975,19.8939,9.2954
133.4,13.0126,19.8953,9.3197
133.6,13.0275,19.893,9.3434
133.8,13.0426,19.8938,9.3681
134,13.0576,19.8937,9.393
134.2,13.0727,19.8948,9.4173
134.4,13.0875,19.8916,9.4414
134.6,13.1026,19.8921,9.4667
134.8,13.1176,19.891,9.4911
135,13.1325,19.8897,9.515
135.2,13.1474,19.8898,9.5396
135.4,13.1627,19.892,9.5647
135.6,13.1775,19.8896,9.5884
135.8,13.1926,19.8906,9.6134
136,13.2076,19.8873,9.6385
136.2,13.2225,19.886,9.6647
136.4,13.2375,19.8849,9.6898
136.6,13.2526,19.8847,9.7156
136.8,13.2675,19.881,9.7418
137,13.2826,19.8822,9.7683
137.2,13.2976,19.8798,9.7943
137.4,13.3126,19.8779,9.8206
137.6,13.3275,19.8742,9.8462
137.8,13.3425,19.8726,9.8725
138,13.3575,19.8703,9.8981
138.2,13.3726,19.8691,9.9247
138.4,13.3875,19.8651,9.9504
138.6,13.4025,19.8628,9.9757
138.8,13.4176,19.8623,10.0023
139,13.4326,19.8588,10.0284
139.2,13.4475,19.8536,10.0546
139.4,13.4625,19.852,10.0814
139.6,13.4776,19.8475,10.1084
139.8,13.4925,19.8441,10.1351
140,13.5076,19.8408,10.1619
140.2,13.5226,19.8368,10.1889
140.4,13.5376,19.8326,10.2172
140.6,13.5526,19.8279,10.2448
140.8,13.5675,19.8216,10.2717
141,13.5825,19.8176,10.2995
141.2,13.5976,19.8157,10.3274
141.4,13.6125,19.809,10.3546
141.6,13.6276,19.8056,10.3823
141.8,13.6425,19.8002,10.4109
142,13.6576,19.7947,10.4388
142.2,13.6724,19.7869,10.4683
142.4,13.6875,19.7838,10.4978
142.6,13.7025,19.7763,10.5267
142.8,13.7176,19.7718,10.5548
143,13.7326,19.7643,10.5832
143.2,13.7477,19.7567,10.6125
143.4,13.7625,19.7473,10.6407
143.6,13.7777,19.7425,10.6698
143.8,13.7925,19.7313,10.6988
144,13.8075,19.7245,10.7291
144.2,13.8225,19.7155,10.7583
144.4,13.8377,19.7078,10.7871
144.6,13.8525,19.6955,10.8173
144.8,13.8677,19.6877,10.847
145,13.8825,19.6744,10.8758
145.2,13.8976,19.6653,10.9049
145.4,13.9125,19.6515,10.9354
145.6,13.9276,19.6402,10.9648
145.8,13.9424,19.626,10.9941
146,13.9577,19.6175,11.0244
146.2,13.9725,19.5987,11.0553
146.4,13.9876,19.5847,11.0865
146.6,14.0025,19.5687,11.117
146.8,14.0176,19.5532,11.1485
147,14.0324,19.5338,11.1787
147.2,14.0476,19.5195,11.209
147.4,14.0625,19.4991,11.2398
147.6,14.0776,19.482,11.271
147.8,14.0926,19.4595,11.3011
148,14.1076,19.4371,11.3316
148.2,14.1224,19.4144,11.3636
148.4,14.1376,19.3933,11.396
148.6,14.1525,19.3648,11.4274
148.8,14.1676,19.3406,11.4593
149,14.1825,19.312,11.4912
149.2,14.1977,19.2847,11.5232
149.4,14.2125,19.2513,11.5549
149.6,14.2276,19.2203,11.5872
149.8,14.2425,19.1839,11.6196
150,14.2575,19.1524,11.6514
150.2,14.2725,19.1125,11.6836
150.4,14.2877,19.0724,11.7169
150.526,14.297,18.9189,11.7376
150.528,14.2972,18.5609,11.7513
150.53,14.2973,17.9912,11.7886
150.532,14.2975,17.2454,11.848
150.534,14.2977,16.3621,11.9383
150.536,14.2979,15.3917,12.0544
150.538,14.2981,14.3617,12.1786
150.54,14.2984,13.2913,12.3075
150.542,14.2987,12.2005,12.4494
150.544,14.2991,11.1083,12.604
150.546,14.2995,10.0315,12.7616
150.548,14.2999,8.9835,12.9191
150.55,14.3004,7.9752,13.076
150.552,14.3008,7.0147,13.2259
150.554,14.3013,6.1102,13.3639
150.556,14.3018,5.2662,13.4886
150.558,14.3023,4.4828,13.5996
150.56,14.3028,3.7607,13.699
150.562,14.3033,3.1015,13.7867
150.564,14.3038,2.5045,13.8619
150.566,14.3042,1.9681,13.9271