File: lab2/data/lab2Test1.csv
Time,Displacement,Force,Strain 1
(s),(mm),(kN),(%)
0,0,0.0001,0.0002
2.6,0.2686,0.0486,0.095
5.2,0.5417,0.1377,0.2299
7.8,0.8146,0.2815,0.486
10.4,1.0877,0.3897,0.7071
13,1.3607,0.4695,0.8924
15.6,1.6337,0.5414,1.0811
18.2,1.9068,0.6107,1.2909
20.8,2.1797,0.6755,1.5283
23.4,2.4528,0.7342,1.7926
26,2.7257,0.7866,2.0786
28.6,2.9987,0.8341,2.3776
31.2,3.2717,0.878,2.6842
33.8,3.5446,0.9181,2.9967
36.4,3.8177,0.9561,3.3136
39,4.0907,0.9913,3.6343
41.6,4.3637,1.024,3.96
44.2,4.6367,1.0544,4.291
46.8,4.9096,1.0822,4.6261
49.4,5.1826,1.1076,4.9662
52,5.4556,1.1308,5.3139
54.6,5.7286,1.1516,5.6689
57.2,6.0017,1.1702,6.0292
59.8,6.2746,1.1864,6.3988
62.4,6.5477,1.201,6.7748
65,6.8206,1.2133,7.1592
67.6,7.0937,1.2239,7.5495
70.2,7.3666,1.233,7.9489
72.8,7.6397,1.2406,8.3542
75.4,7.9127,1.2469,8.7688
78,8.1857,1.2516,9.1879
80.6,8.4587,1.2552,9.6143
83.2,8.7317,1.2577,10.047
85.8,9.0047,1.2591,10.487
88.4,9.2777,1.2595,10.9302
91,9.5506,1.2598,11.3819
93.6,9.8237,1.259,11.8371
96.2,10.0966,1.2579,12.2991
98.8,10.3697,1.256,12.767
101.4,10.6427,1.2536,13.2347
104,10.9157,1.2511,13.7101
106.6,11.1888,1.2482,14.189
109.2,11.4616,1.2448,14.6698
111.8,11.7347,1.2408,15.1526
114.4,12.0077,1.2377,15.6389
117,12.2807,1.2338,16.1294
119.6,12.5537,1.2298,16.6226
122.2,12.8267,1.2256,17.1152
124.8,13.0996,1.2212,17.6119
127.4,13.3727,1.2169,18.1116
130,13.6457,1.2124,18.6122
132.6,13.9187,1.208,19.1118
135.2,14.1916,1.2034,19.6166
137.8,14.4646,1.1988,20.1223
140.4,14.7376,1.1941,20.6275
143,15.0106,1.1896,21.1351
145.6,15.2837,1.1848,21.6442
148.2,15.5566,1.1801,22.1554
150.8,15.8297,1.1751,22.6652
153.4,16.1026,1.1703,23.1805
156,16.3757,1.1652,23.6947
158.6,16.6487,1.1601,24.2078
161.2,16.9217,1.155,24.7251
163.8,17.1946,1.1498,25.244
166.4,17.4676,1.1445,25.7648
169,17.7407,1.1392,26.2875
171.6,18.0137,1.1338,26.8077
174.2,18.2867,1.128,27.3266
176.8,18.5597,1.1225,27.8516
179.4,18.8326,1.1167,28.3788
182,19.1056,1.1107,28.9076
184.6,19.3786,1.1044,29.4357
187.2,19.6517,1.0981,29.9685
189.8,19.9247,1.0919,30.5018
192.4,20.1977,1.0851,31.0334
195,20.4708,1.0781,31.5682
197.6,20.7437,1.071,32.1047
200.2,21.0167,1.0636,32.6442
202.8,21.2897,1.0561,33.1856
205.4,21.5626,1.0481,33.7275
208,21.8356,1.0402,34.2716
210.6,22.1086,1.0319,34.8167
213.2,22.3817,1.0233,35.3652
215.8,22.6548,1.0146,35.9146
218.4,22.9277,1.0056,36.4605
221,23.2007,0.9966,37.0135
223.6,23.4736,0.987,37.5668
226.2,23.7466,0.9772,38.1181
228.8,24.0196,0.9673,38.6725
231.4,24.2927,0.957,39.231
234,24.5657,0.9466,39.7838
236.6,24.8386,0.9354,40.3417
239.2,25.1117,0.9243,40.905
241.8,25.3847,0.9128,41.4639
244.4,25.6577,0.9015,42.0299
247,25.9307,0.8904,42.5932
249.6,26.2036,0.8797,43.154
252.2,26.4767,0.87,43.7164
254.8,26.7496,0.8612,44.2742
257.4,27.0227,0.8538,44.8342
260,27.2957,0.8476,45.3847
262.6,27.5686,0.8426,45.9376
265.2,27.8417,0.8386,46.486
267.8,28.1146,0.8358,47.0345
270.4,28.3876,0.8339,47.5827
273,28.6606,0.8326,48.1276
275.6,28.9336,0.8318,48.6718
278.2,29.2067,0.8316,49.2113
280.8,29.4797,0.8323,49.7486
283.4,29.7528,0.8331,50.2848
286,30.0258,0.8341,50.8274
288.6,30.2988,0.8349,51.3692
291.2,30.5717,0.8359,51.9058
293.8,30.8447,0.8369,52.4474
296.4,31.1177,0.8378,52.9867
299,31.3907,0.8387,53.5258
301.6,31.6637,0.8396,54.068
304.2,31.9367,0.8406,54.6098
306.8,32.2097,0.8414,55.1451
309.4,32.4827,0.8424,55.675
312,32.7556,0.8437,56.2137
314.6,33.0287,0.8447,56.7547
317.2,33.3017,0.8459,57.2944
319.8,33.5746,0.8468,57.8345
322.4,33.8477,0.848,58.3751
325,34.1206,0.8487,58.911
327.6,34.3937,0.8494,59.4511
330.2,34.6667,0.8503,59.9915
332.8,34.9397,0.8507,60.5312
335.4,35.2127,0.8512,61.0724
338,35.4856,0.8519,61.6147
340.6,35.7586,0.8525,62.1579
343.2,36.0316,0.8526,62.6986
345.8,36.3047,0.8529,63.2449
348.4,36.5777,0.853,63.7879
351,36.8506,0.8532,64.3326
353.6,37.1237,0.8533,64.8746
356.2,37.3966,0.8536,65.4189
358.8,37.6696,0.8537,65.9638
361.4,37.9427,0.8541,66.5054
364,38.2156,0.8542,67.0526
366.6,38.4887,0.8542,67.597
369.2,38.7616,0.8543,68.1418
371.8,39.0347,0.8543,68.6798
374.4,39.3077,0.8544,69.2257
377,39.5807,0.8545,69.7729
379.6,39.8537,0.8544,70.3224
382.2,40.1266,0.8545,70.8687
384.8,40.3996,0.8544,71.4146
387.4,40.6726,0.8543,71.9641
390,40.9457,0.8544,72.5154
392.6,41.2187,0.8544,73.0632
395.2,41.4917,0.8547,73.6105
397.8,41.7647,0.8546,74.1621
400.4,42.0376,0.8547,74.7109
403,42.3107,0.8549,75.2618
405.6,42.5837,0.8553,75.8106
408.2,42.8567,0.8555,76.3617
410.8,43.1298,0.8555,76.9084
413.4,43.4027,0.8557,77.4611
416,43.6757,0.8558,78.0137
418.6,43.9487,0.8563,78.5644
421.2,44.2218,0.8567,79.1202
423.8,44.4947,0.8572,79.6626
426.4,44.7676,0.8578,80.215
429,45.0406,0.8583,80.7683
431.6,45.3136,0.8587,81.3184
434.2,45.5866,0.859,81.8746
436.8,45.8597,0.8593,82.4302
439.4,46.1326,0.8595,82.984
442,46.4056,0.8599,83.5406
444.6,46.6786,0.8601,84.0963
447.2,46.9516,0.8606,84.6525
449.8,47.2247,0.8608,85.2094
452.4,47.4976,0.861,85.7671
455,47.7707,0.861,86.3258
457.6,48.0436,0.8609,86.8853
460.2,48.3167,0.8608,87.4364
462.8,48.5897,0.8607,87.9969
465.4,48.8627,0.8604,88.5467
468,49.1357,0.8605,89.1051
470.6,49.4086,0.8604,89.6675
473.2,49.6817,0.8611,90.0342
475.8,49.9547,0.8616,90.1651
478.4,50.2277,0.862,90.1214
481,50.5007,0.8624,90.0841
483.6,50.7736,0.8625,90.0568
486.2,51.0467,0.862,90.1454
488.8,51.3197,0.8619,90.1548
491.4,51.5927,0.8616,90.1109
494,51.8657,0.8616,90.1425
496.6,52.1387,0.8615,90.1596
499.2,52.4118,0.8615,90.1731
501.8,52.6846,0.8615,90.1634
504.4,52.9577,0.8612,90.2083
507,53.2307,0.8614,90.1582
509.6,53.5037,0.8613,90.1641
512.2,53.7767,0.8609,90.1651
514.8,54.0496,0.8614,90.0801
517.4,54.3227,0.8619,90
520,54.5956,0.8628,89.9903
522.6,54.8687,0.863,90.0479
525.2,55.1417,0.8619,90.2142
527.8,55.4146,0.8622,90.1707
530.4,55.6876,0.8622,90.2077
533,55.9606,0.8623,90.1666
535.6,56.2337,0.8626,90.1497
538.2,56.5066,0.8626,90.172
540.8,56.7796,0.862,90.2823
543.4,57.0527,0.862,90.26
546,57.3256,0.8623,90.1985
548.6,57.5987,0.8622,90.2234
551.2,57.8717,0.862,90.2447
553.8,58.1447,0.8621,90.2139
556.4,58.4177,0.8616,90.2972
559,58.6906,0.8613,90.2947
561.6,58.9636,0.861,90.3024
564.2,59.2367,0.8606,90.3
566.8,59.5097,0.8604,90.3048
569.4,59.7827,0.8603,90.2853
572,60.0556,0.8604,90.2694
574.6,60.3286,0.8603,90.2815
577.2,60.6017,0.8602,90.239
579.8,60.8746,0.8604,90.2435
582.4,61.1478,0.8605,90.2427
585,61.4207,0.8608,90.2276
587.6,61.6937,0.8611,90.1951
590.2,61.9667,0.8612,90.1793
592.8,62.2397,0.8613,90.216
595.4,62.5127,0.8613,90.2216
598,62.7857,0.8612,90.256
600.6,63.0587,0.8612,90.2391
603.2,63.3317,0.8611,90.244
605.8,63.6047,0.8614,90.2237
608.4,63.8777,0.8614,90.2474
611,64.1507,0.8615,90.2349
613.6,64.4237,0.8617,90.2179
616.2,64.6966,0.8618,90.1813
618.8,64.9696,0.8622,90.1256
621.4,65.2427,0.8623,90.1949
624,65.5157,0.8622,90.2094
626.6,65.7888,0.8625,90.2066
629.2,66.0617,0.8626,90.186
631.8,66.3347,0.8628,90.2125
634.4,66.6076,0.8629,90.2074
637,66.8807,0.863,90.2036
639.6,67.1537,0.8629,90.2084
642.2,67.4267,0.8631,90.2221
644.8,67.6996,0.8633,90.2206
647.4,67.9726,0.8633,90.2196
650,68.2456,0.8635,90.2298
652.6,68.5187,0.8636,90.234
655.2,68.7916,0.864,90.2245
657.8,69.0647,0.8641,90.2274
660.4,69.3376,0.8644,90.2165
663,69.6106,0.8647,90.1962
665.6,69.8836,0.8647,90.2052
668.2,70.1567,0.865,90.2249
670.8,70.4298,0.8653,90.2327
673.4,70.7027,0.8657,90.2294
676,70.9757,0.8658,90.2202
678.6,71.2486,0.8661,90.2174
681.2,71.5217,0.8663,90.2155
683.8,71.7947,0.867,90.2148
686.4,72.0677,0.8677,90.2056
689,72.3407,0.8681,90.2138
691.6,72.6137,0.8685,90.205
694.2,72.8867,0.8688,90.1935
696.8,73.1597,0.8696,90.1888
699.4,73.4327,0.8697,90.2083
702,73.7057,0.87,90.2095
704.6,73.9786,0.8703,90.2177
707.2,74.2516,0.8707,90.2166
709.8,74.5246,0.8707,90.208
712.4,74.7977,0.8712,90.2178
715,75.0707,0.8713,90.2152
717.6,75.3436,0.8714,90.209
720.2,75.6167,0.8714,90.2056
722.8,75.8897,0.8716,90.1999
725.4,76.1627,0.8715,90.202
728,76.4357,0.8714,90.1899
730.6,76.7086,0.8713,90.2066
733.2,76.9816,0.8714,90.1871
735.8,77.2547,0.8714,90.222
738.4,77.5276,0.8714,90.2306
741,77.8007,0.8714,90.2329
743.6,78.0737,0.8717,90.2197
746.2,78.3466,0.8721,90.1848
748.8,78.6196,0.8725,90.1438
751.4,78.8926,0.8727,90.1359
754,79.1657,0.8729,90.1349
756.6,79.4387,0.8729,90.1965
759.2,79.7117,0.8729,90.2146
761.8,79.9846,0.8732,90.2188
764.4,80.2577,0.8733,90.2158
767,80.5307,0.8734,90.2175
769.6,80.8037,0.8736,90.2092
772.2,81.0767,0.8738,90.1992
774.8,81.3496,0.8739,90.2033
777.4,81.6227,0.8739,90.2048
780,81.8957,0.874,90.1939
782.6,82.1687,0.8741,90.2007
785.2,82.4418,0.8742,90.1916
787.8,82.7147,0.8742,90.207
790.4,82.9877,0.8743,90.2069
793,83.2606,0.8743,90.2094
795.6,83.5336,0.8744,90.1971
798.2,83.8067,0.8743,90.2133
800.8,84.0797,0.8743,90.2186
803.4,84.3528,0.8743,90.1945
806,84.6256,0.8745,90.1857
808.6,84.8988,0.8746,90.2099
811.2,85.1717,0.8744,90.215
813.8,85.4447,0.8748,90.2132
816.4,85.7177,0.875,90.2208
819,85.9906,0.8752,90.2184
821.6,86.2637,0.8755,90.2131
824.2,86.5367,0.8756,90.2134
826.8,86.8097,0.8755,90.2194
829.4,87.0827,0.8756,90.2287
832,87.3556,0.8759,90.2052
834.6,87.6286,0.876,90.2218
837.2,87.9016,0.876,90.2204
839.8,88.1746,0.8763,90.2277
842.4,88.4477,0.8763,90.2175
845,88.7206,0.8766,90.1967
847.6,88.9937,0.8767,90.173
850.2,89.2666,0.8766,90.1623
852.8,89.5398,0.8768,90.177
855.4,89.8127,0.877,90.1845
858,90.0857,0.8773,90.1833
860.6,90.3587,0.8774,90.1969
863.2,90.6316,0.8776,90.1881
865.8,90.9047,0.8777,90.2111
868.4,91.1777,0.878,90.2146
871,91.4507,0.8781,90.2243
873.6,91.7238,0.8782,90.2193
876.2,91.9967,0.8782,90.2142
878.8,92.2697,0.8785,90.201
881.4,92.5426,0.8784,90.2175
884,92.8157,0.8786,90.2125
886.6,93.0887,0.8789,90.2171
889.2,93.3617,0.8788,90.1912
891.8,93.6347,0.8788,90.1917
894.4,93.9077,0.879,90.2036
897,94.1808,0.8792,90.2083
899.6,94.4537,0.8792,90.2217
902.2,94.7267,0.8794,90.2292
904.8,94.9997,0.8795,90.2316
907.4,95.2726,0.8798,90.2341
910,95.5457,0.8801,90.2262
912.6,95.8186,0.8803,90.2346
915.2,96.0917,0.8806,90.2113
917.8,96.3647,0.8809,90.2031
920.4,96.6376,0.8814,90.2103
923,96.9106,0.8812,90.2091
925.6,97.1836,0.8815,90.2113
928.2,97.4566,0.8817,90.2098
930.8,97.7297,0.882,90.214
933.4,98.0026,0.8821,90.2314
936,98.2757,0.8822,90.2233
938.6,98.5487,0.8825,90.2066
941.2,98.8218,0.8826,90.1995
943.8,99.0947,0.8825,90.2096
946.4,99.3677,0.8825,90.2357
949,99.6407,0.8826,90.214
951.6,99.9136,0.883,90.1948
954.2,100.1866,0.8828,90.1822
956.8,100.4597,0.8826,90.2088
959.4,100.7327,0.8829,90.2091
962,101.0057,0.8827,90.2148
964.6,101.2786,0.8826,90.2278
967.2,101.5516,0.8826,90.2373
969.8,101.8246,0.8825,90.2388
972.4,102.0976,0.8826,90.2331
975,102.3707,0.8826,90.2335
977.6,102.6436,0.8825,90.2321
980.2,102.9167,0.8826,90.2334
982.8,103.1897,0.8826,90.2305
985.4,103.4628,0.8828,90.2201
988,103.7357,0.8828,90.2039
990.6,104.0087,0.8826,90.2249
993.2,104.2817,0.8827,90.231
995.8,104.5547,0.883,90.2229
998.4,104.8277,0.883,90.2239
1001,105.1007,0.8832,90.2341
1003.6,105.3737,0.8836,90.2176
1006.2,105.6467,0.8835,90.2138
1008.8,105.9196,0.8835,90.2156
1011.4,106.1927,0.8839,90.2201
1014,106.4656,0.8838,90.2264
1016.6,106.7386,0.8838,90.2291
1019.2,107.0117,0.8839,90.243
1021.8,107.2846,0.8838,90.2366
1024.4,107.5577,0.8837,90.2305
1027,107.8307,0.8838,90.2038
1029.6,108.1037,0.8837,90.2335
1032.2,108.3767,0.8834,90.2378
1034.8,108.6497,0.8835,90.2282
1037.4,108.9226,0.8836,90.2244
1040,109.1956,0.8833,90.2385
1042.6,109.4686,0.8832,90.237
1045.2,109.7417,0.8831,90.2389
1047.8,110.0147,0.8829,90.2411
1050.4,110.2877,0.8829,90.2441
1053,110.5606,0.8829,90.2398
1055.6,110.8336,0.883,90.2208
1058.2,111.1066,0.8828,90.2246
1060.8,111.3796,0.8828,90.2343
1063.4,111.6527,0.8832,90.2284
1066,111.9256,0.8831,90.2287
1068.6,112.1987,0.8829,90.2271
1071.2,112.4717,0.8828,90.2294
1073.8,112.7447,0.8834,90.2267
1076.4,113.0177,0.8839,90.2308
1079,113.2907,0.8844,90.2225
1081.6,113.5637,0.8851,90.2022
1084.2,113.8367,0.8855,90.2192
1086.8,114.1097,0.8858,90.2508
1089.4,114.3827,0.8861,90.2556
1092,114.6557,0.8862,90.2606
1094.6,114.9287,0.8865,90.2618
1097.2,115.2017,0.8868,90.2681
1099.8,115.4747,0.8867,90.2848
1102.4,115.7477,0.8868,90.2895
1105,116.0206,0.8867,90.2871
1107.6,116.2937,0.8865,90.2423
1110.2,116.5666,0.8866,90.2377
1112.8,116.8397,0.8868,90.2193
1115.4,117.1126,0.8868,90.2047
1118,117.3857,0.8868,90.2146
1120.6,117.6587,0.8867,90.2398
1123.2,117.9317,0.8868,90.2275
1125.8,118.2046,0.8866,90.238
1128.4,118.4776,0.8866,90.2409
1131,118.7506,0.8865,90.2523
1133.6,119.0237,0.8861,90.253
1136.2,119.2966,0.886,90.2538
1138.8,119.5696,0.8859,90.2508
1141.4,119.8426,0.8857,90.2397
1144,120.1156,0.8854,90.2424
1146.6,120.3887,0.8854,90.234
1149.2,120.6616,0.8852,90.2277
1151.8,120.9347,0.8851,90.228
1154.4,121.2076,0.8853,90.2226
1157,121.4807,0.8851,90.2465
1159.6,121.7537,0.8848,90.2518
1162.2,122.0268,0.8848,90.2553
1164.8,122.2998,0.8847,90.2469
1167.4,122.5727,0.8844,90.2485
1170,122.8457,0.8844,90.2599
1172.6,123.1187,0.8843,90.2506
1175.2,123.3917,0.8843,90.2427
1177.8,123.6647,0.8842,90.2472
1180.4,123.9377,0.8842,90.2453
1183,124.2107,0.8841,90.2703
1185.6,124.4836,0.8843,90.2656
1188.2,124.7567,0.8844,90.2317
1190.8,125.0297,0.8843,90.2527
1193.4,125.3026,0.8842,90.2426
1196,125.5757,0.8843,90.2484
1198.6,125.8486,0.8844,90.2528
1201.2,126.1217,0.8846,90.2521
1203.8,126.3947,0.8846,90.2546
1206.4,126.6677,0.8851,90.2479
1209,126.9407,0.8853,90.2455
1211.6,127.2136,0.8851,90.2445
1214.2,127.4866,0.8854,90.2499
1216.8,127.7596,0.8855,90.2339
1219.4,128.0326,0.8855,90.255
1222,128.3057,0.8856,90.2449
1224.6,128.5786,0.8855,90.2429
1227.2,128.8516,0.8856,90.2503
1229.8,129.1246,0.8857,90.2581
1232.4,129.3976,0.8854,90.2678
1235,129.6707,0.8854,90.2643
1237.6,129.9436,0.8854,90.27
1240.2,130.2167,0.8855,90.2713
1242.8,130.4896,0.8854,90.2679
1245.4,130.7627,0.8857,90.2697
1248,131.0357,0.8858,90.2703
1250.6,131.3087,0.8857,90.2701
1253.2,131.5817,0.8858,90.2695
1255.8,131.8547,0.8859,90.2452
1258.4,132.1277,0.8858,90.2352
1261,132.4007,0.8857,90.2392
1263.6,132.6737,0.8857,90.2297
1266.2,132.9467,0.8858,90.2265
1268.8,133.2196,0.8857,90.2509
1271.4,133.4927,0.8854,90.2658
1274,133.7657,0.8856,90.2677
1276.6,134.0387,0.8854,90.2649
1279.2,134.3117,0.8855,90.2614
1281.8,134.5847,0.8855,90.2435
1284.4,134.8577,0.8855,90.2411
1287,135.1306,0.8857,90.2677
1289.6,135.4037,0.8858,90.2702
1292.2,135.6767,0.8857,90.2779
1294.8,135.9498,0.886,90.2762
1297.4,136.2227,0.8858,90.2671
1300,136.4957,0.8859,90.2718
1302.6,136.7687,0.8859,90.2728
1305.2,137.0417,0.886,90.2751
1307.8,137.3147,0.8862,90.2523
1310.4,137.5877,0.8864,90.2454
1313,137.8606,0.8862,90.2494
1315.6,138.1336,0.8863,90.2355
1318.2,138.4066,0.8863,90.2323
1320.8,138.6796,0.8864,90.2247
1323.4,138.9527,0.8866,90.2291
1326,139.2256,0.8866,90.2224
1328.6,139.4987,0.8868,90.2158
1331.2,139.7716,0.8867,90.2738
1333.8,140.0447,0.8867,90.2919
1336.4,140.3177,0.8869,90.294
1339,140.5907,0.8869,90.2833
1341.6,140.8637,0.8871,90.2591
1344.2,141.1367,0.8873,90.1994
1346.8,141.4097,0.8872,90.2318
1349.4,141.6826,0.8869,90.2747
1352,141.9557,0.8869,90.258
1354.6,142.2287,0.8871,90.2015
1357.2,142.5016,0.887,90.2215
1359.8,142.7747,0.8869,90.2324
1362.4,143.0476,0.887,90.239
1365,143.3206,0.8869,90.2792
1367.6,143.5938,0.8868,90.2834
1370.2,143.8667,0.8869,90.2844
1372.8,144.1398,0.8869,90.255
1375.4,144.4127,0.8867,90.2865
1378,144.6857,0.8866,90.2872
1380.6,144.9587,0.8866,90.2755
1383.2,145.2317,0.8868,90.2376
1385.8,145.5047,0.8869,90.2544
1388.4,145.7777,0.8865,90.2735
1391,146.0506,0.8864,90.2621
1393.6,146.3237,0.8866,90.2603
1396.2,146.5966,0.8865,90.2537
1398.8,146.8697,0.8867,90.2266
1401.4,147.1426,0.887,90.2172
1404,147.4156,0.887,90.2646
1406.6,147.6886,0.8871,90.2722
1409.2,147.9616,0.8872,90.2846
1411.8,148.2347,0.8873,90.2593
1414.4,148.5076,0.8873,90.2848
1417,148.7807,0.8871,90.2825
1419.6,149.0537,0.8872,90.2832
1422.2,149.3267,0.8873,90.2632
1424.8,149.5997,0.8873,90.2546
1427.4,149.8727,0.8874,90.2524
1430,150.1457,0.8875,90.2586
1432.6,150.4186,0.8875,90.2629
1435.2,150.6917,0.8876,90.2719
1437.8,150.9647,0.8877,90.2516
1440.4,151.2377,0.8876,90.247
1443,151.5107,0.8876,90.2491
1445.6,151.7836,0.8876,90.2449
1448.2,152.0566,0.8876,90.2555
1450.8,152.3296,0.8877,90.2529
1453.4,152.6027,0.8876,90.257
1456,152.8757,0.8875,90.2558
1458.6,153.1487,0.8872,90.2553
1461.2,153.4218,0.8874,90.2808
1463.8,153.6946,0.8875,90.2744
1466.4,153.9677,0.8873,90.2724
1469,154.2407,0.8873,90.2549
1471.6,154.5137,0.8873,90.2695
1474.2,154.7867,0.8875,90.2693
1476.8,155.0597,0.8875,90.2809
1479.4,155.3327,0.8874,90.2821
1482,155.6057,0.8873,90.2662
1484.6,155.8787,0.8874,90.2553
1487.2,156.1516,0.8873,90.2435
1489.8,156.4246,0.8875,90.2734
1492.4,156.6976,0.8876,90.2721
1495,156.9706,0.8877,90.2791
1497.6,157.2437,0.8877,90.2742
1500.2,157.5167,0.888,90.2561
1502.8,157.7896,0.8882,90.252
1505.4,158.0627,0.8883,90.2454
1508,158.3357,0.8884,90.2682
1510.6,158.6087,0.8883,90.267
1513.2,158.8817,0.8884,90.2771
1515.8,159.1546,0.8885,90.2735
1518.4,159.4276,0.8885,90.2794
1521,159.7006,0.8886,90.2781
1523.6,159.9736,0.8888,90.2791
1526.2,160.2467,0.8887,90.281
1528.8,160.5197,0.8889,90.2689
1531.4,160.7927,0.8891,90.26
1534,161.0656,0.889,90.2696
1536.6,161.3386,0.8888,90.2606
1539.2,161.6116,0.889,90.2554
1541.8,161.8846,0.8889,90.2642
1544.4,162.1577,0.8889,90.2663
1547,162.4306,0.8891,90.269
1549.6,162.7037,0.8892,90.2613
1552.2,162.9767,0.8891,90.2561
1554.8,163.2497,0.8892,90.2315
1557.4,163.5227,0.8891,90.2543
1560,163.7957,0.8894,90.2425
1562.6,164.0687,0.8895,90.2313
1565.2,164.3417,0.8896,90.2163
1567.8,164.6147,0.8898,90.2079
1570.4,164.8878,0.8897,90.2063
1573,165.1607,0.8898,90.1695
1575.6,165.4337,0.8892,90.2886
1578.2,165.7066,0.8894,90.2226
1580.8,165.9796,0.8894,90.2165
1583.4,166.2527,0.8892,90.2059
1586,166.5257,0.8892,90.1999
1588.6,166.7987,0.8891,90.1928
1591.2,167.0716,0.8891,90.1858
1593.8,167.3447,0.8889,90.1719
1596.4,167.6177,0.889,90.1609
1599,167.8907,0.8892,90.155
1601.6,168.1637,0.8889,90.1572
1604.2,168.4366,0.8888,90.1624
1606.8,168.7096,0.8888,90.1605
1609.4,168.9826,0.8886,90.1568
1612,169.2557,0.8887,90.1419
1614.6,169.5287,0.8886,90.1324
1617.2,169.8016,0.8885,90.1559
1619.8,170.0747,0.8884,90.1657
1622.4,170.3476,0.8882,90.1822
1625,170.6205,0.8883,90.183
1627.6,170.8936,0.8883,90.1759
1630.2,171.1666,0.8882,90.1731
1632.8,171.4397,0.8884,90.1653
1635.4,171.7126,0.8881,90.1575
1638,171.9857,0.8881,90.138
1640.6,172.2587,0.888,90.1421
1643.2,172.5317,0.888,90.1264
1645.8,172.8047,0.8882,90.1188
1648.4,173.0776,0.888,90.1214
1651,173.3507,0.888,90.1171
1653.6,173.6237,0.8879,90.1128
1656.2,173.8967,0.8879,90.11
1658.8,174.1697,0.8877,90.1047
1661.4,174.4427,0.8878,90.0858
1664,174.7157,0.8876,90.0773
1666.6,174.9886,0.8875,90.0675
1669.2,175.2616,0.8877,90.032
1671.8,175.5347,0.8876,89.9988
1674.4,175.8076,0.8878,90.0032
1677,176.0807,0.8877,90.01
1679.6,176.3537,0.8877,89.9832
1682.2,176.6267,0.888,89.9537
1684.8,176.8997,0.8883,89.9302
1687.4,177.1727,0.8882,89.9368
1690,177.4457,0.8883,89.9382
1692.6,177.7186,0.8883,89.9193
1695.2,177.9916,0.8886,89.9078
1697.8,178.2646,0.8885,89.91
1700.4,178.5377,0.8884,89.9079
1703,178.8107,0.8883,89.9115
1705.6,179.0836,0.8883,89.9209
1708.2,179.3566,0.8881,89.9668
1710.8,179.6296,0.8881,90.0174
1713.4,179.9026,0.888,90.0329
1716,180.1757,0.8877,90.0392
1718.6,180.4486,0.8878,90.0481
1721.2,180.7217,0.8877,90.0342
1723.8,180.9946,0.8876,90.0102
1726.4,181.2677,0.8877,89.9826
1729,181.5407,0.8877,90.0036
1731.6,181.8137,0.8875,89.989
1734.2,182.0867,0.8876,89.9663
1736.8,182.3596,0.8878,89.9199
1739.4,182.6326,0.8878,89.9449
1742,182.9056,0.8877,89.9467
1744.6,183.1786,0.8879,89.937
1747.2,183.4517,0.8878,89.9351
1749.8,183.7246,0.888,89.9304
1752.4,183.9977,0.888,89.9149
1755,184.2706,0.8881,89.8877
1757.6,184.5437,0.888,89.872
1760.2,184.8167,0.8883,89.8606
1762.8,185.0896,0.8883,89.8836
1765.4,185.3627,0.8882,89.8756
1768,185.6357,0.8884,89.8473
1770.6,185.9088,0.8885,89.8176
1773.2,186.1817,0.8886,89.8066
1775.8,186.4547,0.8887,89.7967
1778.4,186.7277,0.8886,89.8307
1781,187.0006,0.8882,89.9538
1783.6,187.2737,0.8866,16.7908
1786.2,187.5467,0.8864,16.8182
1788.8,187.8196,0.8864,16.8064
1791.4,188.0927,0.8861,16.8015
1794,188.3656,0.8862,16.7984
1796.6,188.6386,0.8862,16.7939
1799.2,188.9116,0.8859,16.7922
1801.8,189.1846,0.8858,16.7887
1804.4,189.4577,0.8858,16.7874
1807,189.7306,0.8858,16.785
1809.6,190.0037,0.8857,16.7832
1812.2,190.2766,0.8857,16.7816
1814.8,190.5497,0.8858,16.781
1817.4,190.8227,0.8858,16.779
1820,191.0957,0.8856,16.7775
1822.6,191.3687,0.8858,16.7762
1825.2,191.6416,0.8858,16.776
1827.8,191.9146,0.8861,16.7751
1830.4,192.1876,0.886,16.7733
1833,192.4607,0.8859,16.7733
1835.6,192.7337,0.8859,16.7718
1838.2,193.0066,0.8856,16.7719
1840.8,193.2797,0.8855,16.77
1843.4,193.5526,0.8853,16.7697
1846,193.8257,0.8852,16.7696
1848.6,194.0987,0.885,16.7679
1851.2,194.3716,0.8847,16.7687
1853.8,194.6447,0.8848,16.7666
1856.4,194.9176,0.8846,16.767
1859,195.1908,0.8845,16.7658
1861.6,195.4637,0.8844,16.7657
1864.2,195.7367,0.8845,16.7647
1866.8,196.0097,0.8844,16.7644
1869.4,196.2827,0.8847,16.7635
1872,196.5557,0.8848,16.7632
1874.6,196.8287,0.8848,16.7633
1877.2,197.1016,0.885,16.7616
1879.8,197.3747,0.8851,16.762
1882.4,197.6476,0.8851,16.7613
1885,197.9206,0.8849,16.7609
1887.6,198.1936,0.8852,16.7602
1890.2,198.4667,0.885,16.7597
1892.8,198.7397,0.885,16.7598
1895.4,199.0126,0.8851,16.7594
1898,199.2857,0.885,16.7593
1900.6,199.5586,0.8848,16.7586
1903.2,199.8317,0.8849,16.7585
1905.8,200.1047,0.8846,16.7576
1908.4,200.3777,0.8849,16.7578
1911,200.6507,0.8846,16.757
1913.6,200.9236,0.8847,16.7573
1916.2,201.1966,0.8846,16.7563
1918.8,201.4696,0.8844,16.7559
1921.4,201.7426,0.8844,16.7557
1924,202.0156,0.8845,16.7554
1926.6,202.2886,0.8845,16.7554
1929.2,202.5616,0.8843,16.7545
1931.8,202.8347,0.8844,16.7549
1934.4,203.1076,0.8843,16.7545
1937,203.3807,0.8841,16.7541
1939.6,203.6536,0.8841,16.7543
1942.2,203.9267,0.8842,16.7527
1944.8,204.1997,0.8841,16.7534
1947.4,204.4727,0.8843,16.7528
1950,204.7457,0.8843,16.7537
1952.6,205.0187,0.8843,16.7519
1955.2,205.2917,0.8844,16.7527
1957.8,205.5647,0.8842,16.752
1960.4,205.8377,0.8842,16.7516
1963,206.1107,0.8843,16.7534
1965.6,206.3837,0.8843,16.7498
1968.2,206.6567,0.8842,16.7493
1970.8,206.9296,0.8843,16.7519
1973.4,207.2026,0.8843,16.7518
1976,207.4757,0.8846,16.7513
1978.6,207.7487,0.8841,16.7502
1981.2,208.0217,0.8843,16.7498
1983.8,208.2946,0.8844,16.7501
1986.4,208.5677,0.8845,16.7504
1989,208.8406,0.8847,16.7502
1991.6,209.1137,0.8848,16.7505
1994.2,209.3867,0.885,16.7495
1996.8,209.6596,0.8852,16.7495
1999.4,209.9326,0.8853,16.7488
2002,210.2057,0.8856,16.7483
2004.6,210.4786,0.8856,16.7483
2007.2,210.7517,0.8857,16.7478
2009.8,211.0246,0.8856,16.7479
2012.4,211.2976,0.8857,16.7478
2015,211.5705,0.8857,16.7484
2017.6,211.8436,0.8858,16.7478
2020.2,212.1166,0.8858,16.747
2022.8,212.3896,0.8858,16.7469
2025.4,212.6627,0.8856,16.7464
2028,212.9356,0.8857,16.7463
2030.6,213.2087,0.8857,16.7465
2033.2,213.4817,0.8856,16.7462
2035.8,213.7547,0.8854,16.7461
2038.4,214.0277,0.8853,16.7461
2041,214.3007,0.8852,16.7457
2043.6,214.5737,0.8851,16.746
2046.2,214.8467,0.8849,16.7461
2048.8,215.1197,0.8849,16.7462
2051.4,215.3927,0.8847,16.7458
2054,215.6656,0.8845,16.7459
2056.6,215.9386,0.8845,16.7458
2059.2,216.2116,0.8845,16.746
2061.8,216.4846,0.8845,16.7461
2064.4,216.7577,0.8843,16.7456
2067,217.0307,0.8844,16.7453
2069.6,217.3038,0.8843,16.7451
2072.2,217.5766,0.8843,16.744
2074.8,217.8497,0.8845,16.7437
2077.4,218.1227,0.8844,16.7441
2080,218.3957,0.8845,16.7444
2082.6,218.6687,0.8843,16.7446
2085.2,218.9417,0.8843,16.7441
2087.8,219.2146,0.8842,16.7442
2090.4,219.4877,0.8843,16.7443
2093,219.7606,0.8843,16.7441
2095.6,220.0337,0.8839,16.7432
2098.2,220.3066,0.8842,16.7434
2100.8,220.5796,0.8841,16.7432
2103.4,220.8526,0.8839,16.7427
2106,221.1256,0.8839,16.7427
2108.6,221.3987,0.8838,16.7424
2111.2,221.6716,0.8836,16.742
2113.8,221.9447,0.8836,16.7424
2116.4,222.2177,0.8832,16.7417
2119,222.4907,0.8831,16.7423
2121.6,222.7637,0.8829,16.7421
2124.2,223.0367,0.8828,16.7418
2126.8,223.3097,0.8828,16.7414
2129.4,223.5826,0.8828,16.7411
2132,223.8557,0.8828,16.7413
2134.6,224.1287,0.8828,16.7424
2137.2,224.4017,0.8826,16.7423
2139.8,224.6747,0.8826,16.7423
2142.4,224.9476,0.8827,16.7424
2145,225.2206,0.8826,16.7423
2147.6,225.4936,0.8825,16.742
2150.2,225.7666,0.8824,16.7417
2152.8,226.0397,0.8827,16.7415
2155.4,226.3127,0.8826,16.7417
2158,226.5858,0.8827,16.7422
2160.6,226.8587,0.8824,16.7414
2163.2,227.1317,0.8824,16.7409
2165.8,227.4047,0.8825,16.7402
2168.4,227.6777,0.8823,16.7406
2171,227.9507,0.8823,16.74
2173.6,228.2236,0.882,16.7401
2176.2,228.4966,0.8818,16.74
2178.8,228.7697,0.8815,16.7403
2181.4,229.0426,0.8814,16.7404
2184,229.3157,0.8812,16.7406
2186.6,229.5886,0.881,16.7399
2189.2,229.8616,0.8809,16.7399
2191.8,230.1346,0.8808,16.7392
2194.4,230.4076,0.8807,16.7388
2197,230.6807,0.8806,16.7394
2199.6,230.9536,0.8804,16.7391
2202.2,231.2267,0.8803,16.7401
2204.8,231.4996,0.8802,16.74
2207.4,231.7727,0.8801,16.7399
2210,232.0457,0.8802,16.7397
2212.6,232.3187,0.8799,16.7396
2215.2,232.5917,0.8799,16.7388
2217.8,232.8646,0.8797,16.7388
2220.4,233.1376,0.8796,16.739
2223,233.4107,0.8797,16.7395
2225.6,233.6837,0.8795,16.7396
2228.2,233.9567,0.8795,16.7394
2230.8,234.2296,0.8797,16.7384
2233.4,234.5026,0.8797,16.7383
2236,234.7756,0.8796,16.739
2238.6,235.0486,0.8795,16.7392
2241.2,235.3217,0.8796,16.7396
2243.8,235.5947,0.8794,16.7392
2246.4,235.8677,0.8796,16.7391
2249,236.1407,0.8798,16.7386
2251.6,236.4138,0.8797,16.7378
2254.2,236.6867,0.88,16.7381
2256.8,236.9597,0.88,16.738
2259.4,237.2327,0.8803,16.7378
2262,237.5056,0.8802,16.7384
2264.6,237.7787,0.8801,16.7384
2267.2,238.0517,0.8801,16.7384
2269.8,238.3247,0.8799,16.7383
2272.4,238.5977,0.8798,16.7378
2275,238.8706,0.8796,16.7374
2277.6,239.1436,0.8794,16.7378
2280.2,239.4166,0.8793,16.7375
2282.8,239.6896,0.879,16.737
2285.4,239.9627,0.879,16.7374
2288,240.2356,0.8787,16.7382
2290.6,240.5087,0.8786,16.7382
2293.2,240.7817,0.8784,16.7375
2295.8,241.0547,0.8783,16.737
2298.4,241.3276,0.8781,16.7368
2301,241.6007,0.878,16.7376
2303.6,241.8736,0.878,16.7377
2306.2,242.1466,0.878,16.7368
2308.8,242.4196,0.878,16.7363
2311.4,242.6927,0.8779,16.737
2314,242.9657,0.8778,16.7373
2316.6,243.2387,0.8777,16.7368
2319.2,243.5116,0.8776,16.7365
2321.8,243.7846,0.8776,16.7362
2324.4,244.0576,0.8773,16.7374
2327,244.3306,0.8772,16.7379
2329.6,244.6037,0.8771,16.7368
2332.2,244.8766,0.877,16.7366
2334.8,245.1497,0.877,16.7358
2337.4,245.4227,0.8766,16.7369
2340,245.6957,0.8768,16.737
2342.6,245.9688,0.8767,16.7357
2345.2,246.2417,0.8771,16.7368
2347.8,246.5147,0.8772,16.7371
2350.4,246.7877,0.8775,16.7362
2353,247.0607,0.8777,16.7357
2355.6,247.3337,0.8776,16.7362
2358.2,247.6067,0.8777,16.7367
2360.8,247.8797,0.8778,16.7362
2363.4,248.1526,0.878,16.7356
2366,248.4256,0.8779,16.7357
2368.6,248.6987,0.8778,16.7369
2371.2,248.9716,0.8779,16.7356
2373.8,249.2448,0.878,16.7353
2376.4,249.5176,0.878,16.7364
2379,249.7907,0.8778,16.736
2381.6,250.0637,0.8777,16.7353
2384.2,250.3367,0.8776,16.7361
2386.8,250.6097,0.8776,16.7359
2389.4,250.8827,0.8777,16.7354
2392,251.1556,0.8774,16.7361
2394.6,251.4286,0.8774,16.7353
2397.2,251.7016,0.8775,16.7345
2399.8,251.9747,0.8775,16.7355
2402.4,252.2476,0.8774,16.7358
2405,252.5207,0.8773,16.7346
2407.6,252.7936,0.8775,16.735
2410.2,253.0666,0.8773,16.7358
2412.8,253.3396,0.8774,16.7345
2415.4,253.6126,0.8773,16.7347
2418,253.8857,0.8772,16.7356
2420.6,254.1586,0.8771,16.735
2423.2,254.4317,0.8771,16.7352
2425.8,254.7047,0.877,16.7356
2428.4,254.9777,0.8772,16.7342
2431,255.2507,0.8771,16.7355
2433.6,255.5237,0.8774,16.7345
2436.2,255.7966,0.8772,16.735
2438.8,256.0697,0.8774,16.7347
2441.4,256.3427,0.8777,16.7342
2444,256.6157,0.8776,16.7348
2446.6,256.8887,0.8779,16.7341
2449.2,257.1617,0.878,16.7355
2451.8,257.4346,0.8777,16.734
2454.4,257.7076,0.878,16.7352
2457,257.9807,0.8778,16.7339
2459.6,258.2536,0.8781,16.7347
2462.2,258.5267,0.8784,16.734
2464.8,258.7996,0.8786,16.7346
2467.4,259.0727,0.8786,16.7342
2470,259.3456,0.8785,16.7352
2472.6,259.6187,0.8789,16.7342
2475.2,259.8917,0.8786,16.7348
2477.8,260.1646,0.8787,16.7339
2480.4,260.4377,0.8785,16.7346
2483,260.7106,0.8785,16.7341
2485.6,260.9836,0.8783,16.7338
2488.2,261.2567,0.8782,16.7347
2490.8,261.5296,0.8779,16.7341
2493.4,261.8026,0.8778,16.7346
2496,262.0756,0.8774,16.734
2498.6,262.3486,0.8775,16.7339
2501.2,262.6216,0.8771,16.7344
2503.8,262.8947,0.877,16.7332
2506.4,263.1677,0.8768,16.7343
2509,263.4406,0.8766,16.7341
2511.6,263.7137,0.8764,16.7329
2514.2,263.9867,0.8762,16.7337
2516.8,264.2597,0.8759,16.7347
2519.4,264.5327,0.8758,16.7339
2522,264.8056,0.8754,16.7334
2524.6,265.0787,0.8752,16.7332
2527.2,265.3517,0.8753,16.7344
2529.8,265.6246,0.8751,16.7336
2532.4,265.8977,0.8752,16.7334
2535,266.1706,0.8749,16.7338
2537.6,266.4436,0.875,16.7343
2540.2,266.7166,0.8751,16.7332
2542.8,266.9897,0.875,16.7331
2545.4,267.2627,0.8748,16.7331
2548,267.5356,0.8745,16.7338
2550.6,267.8087,0.8744,16.7331
2553.2,268.0816,0.8744,16.733
2555.8,268.3547,0.8742,16.7334
2558.4,268.6277,0.8742,16.7337
2561,268.9007,0.8741,16.7332
2563.6,269.1737,0.8738,16.733
2566.2,269.4467,0.8737,16.7329
2568.8,269.7197,0.8735,16.7335
2571.4,269.9927,0.8734,16.7335
2574,270.2656,0.8734,16.7335
2576.6,270.5388,0.8733,16.7328
2579.2,270.8116,0.8731,16.7328
2581.8,271.0846,0.8729,16.733
2584.4,271.3576,0.8729,16.7338
2587,271.6306,0.8729,16.7337
2589.6,271.9037,0.8726,16.7328
2592.2,272.1766,0.8726,16.7324
2594.8,272.4497,0.8725,16.7333
2597.4,272.7226,0.8727,16.7335
2600,272.9957,0.8726,16.7321
2602.6,273.2686,0.8726,16.7324
2605.2,273.5417,0.8725,16.7328
2607.8,273.8147,0.8725,16.7334
2610.4,274.0876,0.8723,16.7332
2613,274.3607,0.8724,16.7326
2615.6,274.6336,0.8722,16.7324
2618.2,274.9067,0.8722,16.7325
2620.8,275.1797,0.8721,16.7331
2623.4,275.4526,0.8721,16.7335
2626,275.7256,0.8721,16.7328
2628.6,275.9986,0.8718,16.7327
2631.2,276.2717,0.8719,16.734
2633.8,276.5447,0.8717,16.7336
2636.4,276.8177,0.8714,16.7323
2639,277.0907,0.8712,16.7323
2641.6,277.3636,0.8713,16.7323
2644.2,277.6367,0.8712,16.7331
2646.8,277.9097,0.8712,16.7332
2649.4,278.1827,0.8714,16.733
2652,278.4557,0.8715,16.7324
2654.6,278.7287,0.8715,16.732
2657.2,279.0017,0.8715,16.7324
2659.8,279.2747,0.8715,16.7329
2662.4,279.5477,0.8711,16.7329
2665,279.8207,0.8714,16.7329
2667.6,280.0936,0.8712,16.7321
2670.2,280.3666,0.8712,16.7323
2672.8,280.6396,0.871,16.7323
2675.4,280.9126,0.871,16.7336
2678,281.1857,0.8709,16.7331
2680.6,281.4586,0.8709,16.7325
2683.2,281.7317,0.871,16.7322
2685.8,282.0047,0.8709,16.7319
2688.4,282.2777,0.8707,16.732
2691,282.5507,0.8708,16.7322
2693.6,282.8237,0.8706,16.7323
2696.2,283.0966,0.8704,16.7321
2698.8,283.3697,0.8703,16.7326
2701.4,283.6426,0.8702,16.7329
2704,283.9157,0.8701,16.7327
2706.6,284.1887,0.8701,16.7324
2709.2,284.4617,0.8701,16.7327
2711.8,284.7345,0.8699,16.7328
2714.4,285.0076,0.8697,16.7328
2717,285.2806,0.8697,16.7326
2719.6,285.5536,0.8696,16.7329
2722.2,285.8268,0.8697,16.7323
2724.8,286.0997,0.8698,16.7319
2727.4,286.3727,0.8697,16.7315
2730,286.6457,0.8697,16.7316
2732.6,286.9187,0.8695,16.7319
2735.2,287.1917,0.8696,16.7319
2737.8,287.4647,0.8695,16.7328
2740.4,287.7377,0.8696,16.7324
2743,288.0107,0.8697,16.7324
2745.6,288.2837,0.8697,16.7321
2748.2,288.5568,0.8698,16.7317
2750.8,288.8297,0.8697,16.7319
2753.4,289.1027,0.8698,16.7316
2756,289.3756,0.8696,16.731
2758.6,289.6486,0.8693,16.7314
2761.2,289.9216,0.8692,16.7315
2763.8,290.1947,0.8689,16.7315
2766.4,290.4677,0.8687,16.7311
2769,290.7406,0.8683,16.7315
2771.6,291.0137,0.868,16.7314
2774.2,291.2867,0.8677,16.7316
2776.8,291.5597,0.8674,16.7316
2779.4,291.8327,0.8671,16.7319
2782,292.1057,0.8668,16.7322
2784.6,292.3787,0.8663,16.732
2787.2,292.6516,0.8665,16.7314
2789.8,292.9247,0.8663,16.7319
2792.4,293.1977,0.8661,16.7312
2795,293.4706,0.8657,16.7311
2797.6,293.7437,0.8654,16.7308
2800.2,294.0165,0.8648,16.7315
2802.8,294.2896,0.8645,16.7322
2805.4,294.5626,0.8641,16.7322
2808,294.8357,0.8634,16.7318
2810.6,295.1087,0.8629,16.732
2813.2,295.3817,0.8624,16.7313
2815.8,295.6548,0.8618,16.7308
2818.4,295.9276,0.8611,16.7312
2821,296.2007,0.8604,16.7309
2823.6,296.4737,0.8597,16.7317
2826.2,296.7467,0.859,16.732
2828.8,297.0197,0.8584,16.7314
2831.4,297.2927,0.8576,16.7309
2834,297.5657,0.857,16.7315
2836.6,297.8387,0.8564,16.7312
2839.2,298.1117,0.8555,16.7308
2841.8,298.3847,0.8547,16.7324
2844.4,298.6576,0.854,16.7317
2847,298.9306,0.8534,16.7308
2849.6,299.2036,0.8527,16.7302
2852.2,299.4767,0.8518,16.7309
2854.8,299.7497,0.8512,16.7317
2857.4,300.0227,0.8503,16.7314
2860,300.2957,0.8497,16.7315
2862.6,300.5687,0.8489,16.731
2865.2,300.8417,0.8485,16.7309
2867.8,301.1147,0.8477,16.7308
2870.4,301.3876,0.8472,16.7306
2873,301.6606,0.8466,16.7308
2875.6,301.9336,0.8457,16.7313
2878.2,302.2066,0.845,16.732
2880.8,302.4797,0.8438,16.7307
2883.4,302.7526,0.843,16.7305
2886,303.0256,0.8418,16.7319
2888.6,303.2986,0.8405,16.7306
2891.2,303.5716,0.8391,16.7306
2893.8,303.8446,0.838,16.7319
2896.4,304.1176,0.8367,16.7309
2899,304.3907,0.8354,16.7315
2901.6,304.6636,0.834,16.7316
2904.2,304.9367,0.8329,16.731
2906.8,305.2097,0.8315,16.7315
2909.4,305.4827,0.8299,16.731
2912,305.7557,0.8284,16.7309
2914.6,306.0286,0.8269,16.7316
2917.2,306.3017,0.8254,16.731
2919.8,306.5747,0.824,16.7307
2922.4,306.8477,0.8223,16.7311
2925,307.1208,0.8208,16.7317
2927.6,307.3937,0.819,16.7308
2930.2,307.6667,0.8173,16.7312
2932.8,307.9396,0.816,16.7317
2935.4,308.2126,0.8144,16.7304
2938,308.4857,0.8131,16.7316
2940.6,308.7587,0.8115,16.7312
2943.2,309.0318,0.81,16.7306
2945.8,309.3047,0.8082,16.7315
2948.4,309.5778,0.8067,16.7312
2951,309.8507,0.8051,16.7309
2953.6,310.1237,0.8033,16.7306
2956.2,310.3967,0.8017,16.7313
2958.8,310.6696,0.8003,16.7312
2961.4,310.9426,0.799,16.7309
2964,311.2156,0.798,16.7308
2966.6,311.4886,0.7968,16.731
2969.2,311.7617,0.796,16.7313
2971.8,312.0346,0.7954,16.7306
2974.4,312.3076,0.7951,16.7301
2977,312.5806,0.7952,16.7313
2979.6,312.8536,0.7954,16.7315
2982.2,313.1266,0.7959,16.7305
2984.8,313.3996,0.7969,16.7299
2987.4,313.6727,0.7983,16.7309
2990,313.9456,0.7993,16.7312
2992.6,314.2187,0.8007,16.7299
2995.2,314.4917,0.8024,16.7308
2997.8,314.7647,0.8041,16.7314
3000.4,315.0377,0.8062,16.7307
3003,315.3106,0.8081,16.7307
3005.6,315.5836,0.8103,16.7315
3008.2,315.8567,0.8123,16.7311
3010.8,316.1297,0.8147,16.73
3013.4,316.4027,0.8168,16.7314
3016,316.6756,0.8193,16.7305
3018.6,316.9487,0.8216,16.7305
3021.2,317.2216,0.8241,16.7312
3023.8,317.4947,0.8266,16.7311
3026.4,317.7677,0.8293,16.7304
3029,318.0406,0.8318,16.7304
3031.6,318.3137,0.8344,16.7311
3034.2,318.5866,0.8371,16.7299
3036.8,318.8597,0.8402,16.7306
3039.4,319.1328,0.8428,16.7311
3042,319.4057,0.8456,16.7303
3044.6,319.6787,0.8485,16.7304
3047.2,319.9516,0.8511,16.7305
3049.8,320.2246,0.8541,16.7305
3052.4,320.4977,0.8568,16.7314
3055,320.7707,0.86,16.7302
3057.6,321.0437,0.863,16.7314
3060.2,321.3166,0.8659,16.7307
3062.8,321.5897,0.869,16.7311
3065.4,321.8626,0.8719,16.7303
3068,322.1356,0.8748,16.731
3070.6,322.4087,0.878,16.7297
3073.2,322.6816,0.8805,16.7315
3075.8,322.9547,0.8831,16.7306
3078.4,323.2276,0.886,16.7315
3081,323.5007,0.8888,16.7303
3083.6,323.7737,0.8912,16.7313
3086.2,324.0467,0.8939,16.7301
3088.8,324.3196,0.8966,16.7306
3091.4,324.5926,0.899,16.7305
3094,324.8656,0.9014,16.7308
3096.6,325.1387,0.9039,16.7315
3099.2,325.4117,0.9063,16.7304
3101.8,325.6847,0.9088,16.7312
3104.4,325.9576,0.9112,16.7308
3107,326.2307,0.9133,16.7307
3109.6,326.5036,0.9155,16.7304
3112.2,326.7766,0.9177,16.7309
3114.8,327.0497,0.9197,16.7311
3117.4,327.3226,0.9214,16.7299
3120,327.5957,0.9232,16.7312
3122.6,327.8687,0.925,16.7307
3125.2,328.1417,0.9266,16.7313
3127.8,328.4147,0.9282,16.7304
3130.4,328.6877,0.9299,16.7309
3133,328.9607,0.9315,16.7309
3135.6,329.2336,0.933,16.7305
3138.2,329.5066,0.9346,16.7315
3140.8,329.7797,0.9359,16.7297
3143.4,330.0527,0.9374,16.7312
3146,330.3257,0.939,16.7306
3148.6,330.5986,0.9404,16.7308
3151.2,330.8716,0.9419,16.7306
3153.8,331.1447,0.9432,16.7307
3156.4,331.4176,0.9446,16.7314
3159,331.6907,0.9458,16.7299
3161.6,331.9636,0.9471,16.7306
3164.2,332.2367,0.9484,16.7308
3166.8,332.5096,0.9497,16.73
3169.4,332.7827,0.9505,16.7312
3172,333.0557,0.9518,16.7303
3174.6,333.3286,0.9529,16.7303
3177.2,333.6017,0.9538,16.731
3179.8,333.8746,0.9548,16.7302
3182.4,334.1477,0.9556,16.7306
3185,334.4207,0.9563,16.731
3187.6,334.6936,0.9572,16.7299
3190.2,334.9667,0.9579,16.7305
3192.8,335.2396,0.9585,16.7312
3195.4,335.5126,0.9592,16.731
3198,335.7856,0.9599,16.7304
3200.6,336.0587,0.9602,16.731
3203.2,336.3317,0.9607,16.7307
3205.8,336.6046,0.9612,16.7304
3208.4,336.8777,0.9617,16.7314
3211,337.1506,0.9619,16.7305
3213.6,337.4237,0.9623,16.7299
3216.2,337.6967,0.9627,16.7311
3218.8,337.9697,0.9633,16.7313
3221.4,338.2427,0.9635,16.7308
3224,338.5156,0.964,16.7301
3226.6,338.7887,0.9644,16.7302
3229.2,339.0617,0.9648,16.7305
3231.8,339.3346,0.9654,16.7312
3234.4,339.6077,0.9655,16.7312
3237,339.8806,0.9659,16.7302
3239.6,340.1537,0.9662,16.7302
3242.2,340.4267,0.9665,16.7305
3244.8,340.6997,0.9666,16.7305
3247.4,340.9727,0.9668,16.7308
3250,341.2456,0.9671,16.7314
3252.6,341.5187,0.9672,16.7308
3255.2,341.7916,0.9675,16.7307
3257.8,342.0647,0.9676,16.7307
3260.4,342.3377,0.9676,16.7301
3263,342.6106,0.9678,16.7305
3265.6,342.8836,0.9678,16.73
3268.2,343.1566,0.968,16.7302
3270.8,343.4296,0.968,16.7303
3273.4,343.7027,0.968,16.73
3276,343.9756,0.968,16.7304
3278.6,344.2486,0.968,16.7302
3281.2,344.5216,0.9679,16.7301
3283.8,344.7946,0.9679,16.7313
3286.4,345.0677,0.9679,16.7309
3289,345.3406,0.968,16.7309
3291.6,345.6137,0.968,16.7311
3294.2,345.8866,0.9679,16.731
3296.8,346.1597,0.968,16.7312
3299.4,346.4327,0.968,16.7305
3302,346.7057,0.968,16.7301
3304.6,346.9787,0.9679,16.7305
3307.2,347.2516,0.9682,16.7297
3309.8,347.5247,0.9682,16.7306
3312.4,347.7977,0.9683,16.7305
3315,348.0707,0.9684,16.7309
3317.6,348.3438,0.9684,16.7305
3320.2,348.6166,0.9685,16.7303
3322.8,348.8897,0.9685,16.7302
3325.4,349.1626,0.9688,16.73
3328,349.4356,0.9688,16.7306
3330.6,349.7087,0.969,16.7314
3333.2,349.9817,0.9693,16.7308
3335.8,350.2547,0.9692,16.7302
3338.4,350.5276,0.9695,16.73
3341,350.8007,0.9697,16.7303
3343.6,351.0737,0.9699,16.7309
3346.2,351.3467,0.9699,16.7309
3348.8,351.6197,0.9703,16.7304
3351.4,351.8926,0.9704,16.7301
3354,352.1657,0.9705,16.7302
3356.6,352.4387,0.9708,16.7305
3359.2,352.7116,0.9708,16.7305
3361.8,352.9847,0.9711,16.7303
3364.4,353.2576,0.9713,16.7304
3367,353.5306,0.9714,16.7305
3369.6,353.8036,0.9717,16.7308
3372.2,354.0766,0.9717,16.7305
3374.8,354.3497,0.9719,16.7302
3377.4,354.6227,0.9723,16.7297
3380,354.8957,0.9726,16.7305
3382.6,355.1686,0.9729,16.7311
3385.2,355.4416,0.973,16.731
3387.8,355.7147,0.9733,16.7311
3390.4,355.9877,0.9738,16.7326
3393,356.2607,0.9739,16.7316
3395.6,356.5337,0.9745,16.7311
3398.2,356.8067,0.9749,16.7311
3400.8,357.0797,0.9752,16.7309
3403.4,357.3527,0.9757,16.7303
3406,357.6257,0.9758,16.7306
3408.6,357.8986,0.9762,16.7307
3411.2,358.1716,0.9766,16.7312
3413.8,358.4446,0.9772,16.7305
3416.4,358.7176,0.9774,16.7308
3419,358.9907,0.978,16.7312
3421.6,359.2637,0.9783,16.7311
3424.2,359.5367,0.9788,16.7305
3426.8,359.8097,0.9794,16.7309
3429.4,360.0827,0.9795,16.7305
3432,360.3557,0.9801,16.7312
3434.6,360.6287,0.9804,16.731
3437.2,360.9017,0.9808,16.7307
3439.8,361.1747,0.981,16.7307
3442.4,361.4476,0.9814,16.7304
3445,361.7207,0.9819,16.7309
3447.6,361.9937,0.9822,16.7306
3450.2,362.2667,0.9826,16.7309
3452.8,362.5396,0.9829,16.7307
3455.4,362.8127,0.9836,16.7304
3458,363.0856,0.9836,16.7308
3460.6,363.3586,0.9841,16.731
3463.2,363.6317,0.9846,16.7308
3465.8,363.9047,0.9852,16.7309
3468.4,364.1777,0.9857,16.7314
3471,364.4506,0.9861,16.7322
3473.6,364.7237,0.9865,16.7319
3476.2,364.9967,0.9869,16.731
3478.8,365.2697,0.9874,16.7307
3481.4,365.5427,0.9877,16.7309
3484,365.8156,0.9882,16.7308
3486.6,366.0886,0.9886,16.731
3489.2,366.3617,0.9889,16.7311
3491.8,366.6347,0.9896,16.7309
3494.4,366.9077,0.99,16.7314
3497,367.1806,0.9903,16.7317
3499.6,367.4536,0.9911,16.732
3502.2,367.7266,0.9915,16.7313
3504.8,367.9996,0.992,16.7307
3507.4,368.2727,0.9924,16.7302
3510,368.5457,0.9929,16.7308
3512.6,368.8188,0.9935,16.7317
3515.2,369.0917,0.9939,16.7318
3517.8,369.3647,0.9944,16.7309
3520.4,369.6377,0.9949,16.7306
3523,369.9106,0.9955,16.7311
3525.6,370.1837,0.9958,16.7317
3528.2,370.4566,0.9962,16.7316
3530.8,370.7296,0.9964,16.7305
3533.4,371.0027,0.997,16.7309
3536,371.2757,0.9973,16.7316
3538.6,371.5487,0.9976,16.7315
3541.2,371.8216,0.9979,16.7313
3543.8,372.0946,0.9982,16.7302
3546.4,372.3676,0.9985,16.7308
3549,372.6406,0.9988,16.7318
3551.6,372.9137,0.9992,16.7312
3554.2,373.1866,0.9994,16.7307
3556.8,373.4597,1.0001,16.7314
3559.4,373.7326,1.0003,16.7317
3562,374.0057,1.0007,16.7312
3564.6,374.2787,1.0011,16.7303
3567.2,374.5517,1.0014,16.7317
3569.8,374.8247,1.0018,16.731
3572.4,375.0976,1.0023,16.7308
3575,375.3707,1.0028,16.7315
3577.6,375.6437,1.0034,16.7307
3580.2,375.9167,1.0036,16.7306
3582.8,376.1897,1.0044,16.7312
3585.4,376.4626,1.0043,16.7316
3588,376.7356,1.005,16.7308
3590.6,377.0086,1.0053,16.7312
3593.2,377.2816,1.0056,16.7312
3595.8,377.5547,1.0063,16.7306
3598.4,377.8276,1.0063,16.7316
3601,378.1007,1.0068,16.7314
3603.6,378.3737,1.0072,16.7307
3606.2,378.6467,1.0077,16.732
3608.8,378.9197,1.0079,16.731
3611.4,379.1927,1.0084,16.7302
3614,379.4657,1.0088,16.7318
3616.6,379.7386,1.0091,16.7312
3619.2,380.0117,1.0096,16.7305
3621.8,380.2847,1.0101,16.7315
3624.4,380.5577,1.0103,16.7321
3627,380.8307,1.0105,16.7309
3629.6,381.1036,1.011,16.7313
3632.2,381.3766,1.0115,16.7317
3634.8,381.6497,1.0117,16.7311
3637.4,381.9226,1.0121,16.7306
3640,382.1957,1.0123,16.731
3642.6,382.4686,1.0127,16.7315
3645.2,382.7417,1.0131,16.7312
3647.8,383.0146,1.0133,16.731
3650.4,383.2877,1.0138,16.7317
3653,383.5607,1.0141,16.7316
3655.6,383.8336,1.0145,16.7309
3658.2,384.1066,1.0151,16.7308
3660.8,384.3796,1.0155,16.7314
3663.4,384.6526,1.016,16.7306
3666,384.9257,1.0165,16.7311
3668.6,385.1986,1.0169,16.7318
3671.2,385.4716,1.0172,16.7305
3673.8,385.7446,1.0176,16.7314
3676.4,386.0176,1.018,16.7315
3679,386.2906,1.0183,16.7306
3681.6,386.5636,1.0188,16.7319
3684.2,386.8367,1.0192,16.7306
3686.8,387.1096,1.0197,16.7317
3689.4,387.3828,1.0202,16.7315
3692,387.6557,1.0205,16.7309
3694.6,387.9287,1.021,16.7318
3697.2,388.2017,1.0213,16.7306
3699.8,388.4746,1.0218,16.731
3702.4,388.7476,1.0223,16.7315
3705,389.0207,1.0224,16.7309
3707.6,389.2937,1.0228,16.7316
3710.2,389.5667,1.0233,16.7316
3712.8,389.8397,1.0234,16.731
3715.4,390.1127,1.0238,16.7317
3718,390.3857,1.0242,16.7309
3720.6,390.6587,1.0247,16.7309
3723.2,390.9317,1.0248,16.7311
3725.8,391.2047,1.0252,16.731
3728.4,391.4777,1.0258,16.7314
3731,391.7506,1.0261,16.7308
3733.6,392.0237,1.0266,16.7318
3736.2,392.2967,1.0268,16.7305
3738.8,392.5697,1.0273,16.7312
3741.4,392.8427,1.0275,16.731
3744,393.1156,1.0278,16.731
3746.6,393.3886,1.0284,16.7312
3749.2,393.6617,1.0288,16.7305
3751.8,393.9346,1.029,16.7321
3754.4,394.2077,1.0294,16.7306
3757,394.4806,1.0297,16.7317
3759.6,394.7536,1.0299,16.7311
3762.2,395.0266,1.0304,16.7317
3764.8,395.2997,1.0308,16.7311
3767.4,395.5726,1.0312,16.7314
3770,395.8456,1.0315,16.7314
3772.6,396.1187,1.032,16.731
3775.2,396.3916,1.0322,16.7309
3777.8,396.6647,1.0325,16.7304
3780.4,396.9377,1.0327,16.7312
3783,397.2107,1.0331,16.7305
3785.6,397.4837,1.0335,16.7312
3788.2,397.7566,1.0338,16.7307
3790.8,398.0297,1.034,16.732
3793.4,398.3026,1.0346,16.7306
3796,398.5757,1.0348,16.7316
3798.6,398.8487,1.0351,16.7311
3801.2,399.1216,1.0353,16.7315
3803.8,399.3947,1.0356,16.7309
3806.4,399.6677,1.0359,16.7306
3809,399.9407,1.0363,16.7315
3811.6,400.2137,1.0364,16.7306
3814.2,400.4866,1.0367,16.7319
3816.8,400.7597,1.037,16.7309
3819.4,401.0326,1.0372,16.7315
3822,401.3057,1.0373,16.7306
3824.6,401.5787,1.0376,16.7317
3827.2,401.8517,1.0376,16.7308
3829.8,402.1247,1.0379,16.7316
3832.4,402.3977,1.038,16.7311
3835,402.6707,1.0381,16.7315
3837.6,402.9436,1.0385,16.7309
3840.2,403.2166,1.0385,16.7309
3842.8,403.4897,1.0387,16.7312
3845.4,403.7626,1.0388,16.7308
3848,404.0356,1.0388,16.7314
3850.6,404.3086,1.0388,16.7318
3853.2,404.5816,1.0389,16.7308
3855.8,404.8547,1.0389,16.7314
3858.4,405.1276,1.0389,16.7315
3861,405.4007,1.0387,16.7307
3863.6,405.6736,1.0385,16.7319
3866.2,405.9467,1.0384,16.7308
3868.8,406.2197,1.038,16.7307
3871.4,406.4927,1.0378,16.7316
3874,406.7657,1.0372,16.7309
3876.6,407.0386,1.0363,16.7307
3879.2,407.3116,1.0356,16.7314
3881.8,407.5847,1.0346,16.7307
3884.4,407.8577,1.0334,16.7308
3887,408.1307,1.0316,16.7311
3889.6,408.4036,1.0294,16.7302
3892.2,408.6767,1.0262,16.7314
3894.8,408.9496,1.0212,16.7311
3897.4,409.2227,1.0106,16.7309
3898.942,409.3848,0.1224,16.7299