File: lab1/aidenData.csv
Time,Displacement,Force,Strain 1
(s),(mm),(kN),(%)
0,0,0.0001,-0.0002
0.2,0.0119,0.0236,-0.0104
0.4,0.0267,0.0371,-0.0155
0.6,0.0417,0.0435,-0.0177
0.8,0.0567,0.0468,-0.0184
1,0.0718,0.0505,-0.0175
1.2,0.0868,0.0514,-0.0157
1.4,0.1016,0.053,-0.0147
1.6,0.1166,0.0561,-0.013
1.8,0.1317,0.0602,-0.01
2,0.1467,0.0625,-0.0058
2.2,0.1616,0.0654,-0.0028
2.4,0.1767,0.0713,0.0018
2.6,0.1918,0.0745,0.0065
2.8,0.2067,0.079,0.0122
3,0.2217,0.0868,0.0189
3.2,0.2367,0.0951,0.0276
3.4,0.2517,0.113,0.0384
3.6,0.2667,0.1366,0.0537
3.8,0.2817,0.1812,0.0742
4,0.2967,0.2698,0.0921
4.2,0.3117,0.3542,0.1063
4.4,0.3267,0.4362,0.1166
4.6,0.3416,0.5111,0.1238
4.8,0.3567,0.5806,0.1288
5,0.3717,0.6411,0.1327
5.2,0.3867,0.6959,0.1342
5.4,0.4017,0.7456,0.1352
5.6,0.4168,0.7937,0.1357
5.8,0.4318,0.8388,0.1355
6,0.4467,0.8831,0.1358
6.2,0.4617,0.9269,0.135
6.4,0.4766,0.9719,0.1336
6.6,0.4917,1.0194,0.1322
6.8,0.5067,1.0676,0.1311
7,0.5217,1.1159,0.13
7.2,0.5367,1.1645,0.1285
7.4,0.5518,1.2126,0.1265
7.6,0.5666,1.2609,0.1253
7.8,0.5816,1.3119,0.1243
8,0.5967,1.3647,0.1232
8.2,0.6118,1.4212,0.1219
8.4,0.6267,1.4824,0.121
8.6,0.6417,1.5468,0.1213
8.8,0.6567,1.6133,0.1213
9,0.6717,1.6837,0.1204
9.2,0.6867,1.7549,0.1199
9.4,0.7017,1.8299,0.1197
9.6,0.7166,1.9082,0.1198
9.8,0.7318,1.9915,0.12
10,0.7467,2.0745,0.1192
10.2,0.7617,2.1609,0.1186
10.4,0.7767,2.2494,0.119
10.6,0.7917,2.3426,0.1191
10.8,0.8066,2.4353,0.1189
11,0.8217,2.5328,0.1183
11.2,0.8367,2.6318,0.1181
11.4,0.8518,2.7361,0.1186
11.6,0.8667,2.8378,0.1178
11.8,0.8817,2.9446,0.1178
12,0.8967,3.0516,0.1183
12.2,0.9117,3.1627,0.1189
12.4,0.9266,3.2727,0.1192
12.6,0.9417,3.3881,0.1186
12.8,0.9567,3.5046,0.1193
13,0.9717,3.6264,0.1193
13.2,0.9867,3.7463,0.1198
13.4,1.0017,3.8694,0.1196
13.6,1.0166,3.9944,0.1199
13.8,1.0317,4.1243,0.1204
14,1.0466,4.2529,0.1211
14.2,1.0617,4.3877,0.1214
14.4,1.0767,4.5223,0.1213
14.6,1.0917,4.6608,0.1219
14.8,1.1066,4.798,0.1227
15,1.1217,4.9405,0.1226
15.2,1.1366,5.0815,0.1228
15.4,1.1517,5.2278,0.1236
15.6,1.1666,5.3716,0.1244
15.8,1.1817,5.5205,0.1248
16,1.1967,5.6704,0.1249
16.2,1.2118,5.8241,0.1253
16.4,1.2266,5.9727,0.1258
16.6,1.2416,6.1286,0.1274
16.8,1.2566,6.2828,0.1266
17,1.2717,6.4407,0.1278
17.2,1.2866,6.5968,0.1283
17.4,1.3017,6.7582,0.1295
17.6,1.3167,6.9189,0.1297
17.8,1.3317,7.0822,0.1304
18,1.3466,7.2426,0.1309
18.2,1.3616,7.4077,0.1324
18.4,1.3766,7.5726,0.1328
18.6,1.3917,7.7425,0.1333
18.8,1.4066,7.9073,0.1345
19,1.4217,8.08,0.1355
19.2,1.4367,8.2509,0.1361
19.4,1.4517,8.4216,0.1368
19.6,1.4666,8.5928,0.1382
19.8,1.4816,8.7668,0.14
20,1.4967,8.9419,0.1407
20.2,1.5117,9.1192,0.1414
20.4,1.5267,9.2944,0.1437
20.6,1.5416,9.4715,0.1454
20.8,1.5567,9.6505,0.1462
21,1.5716,9.8281,0.1475
21.2,1.5866,10.0059,0.149
21.4,1.6016,10.1875,0.1507
21.6,1.6167,10.3694,0.1525
21.8,1.6316,10.551,0.1538
22,1.6467,10.7345,0.1559
22.2,1.6617,10.9179,0.1578
22.4,1.6767,11.1027,0.1598
22.6,1.6916,11.2869,0.1605
22.8,1.7067,11.4715,0.1637
23,1.7215,11.6575,0.1655
23.2,1.7367,11.849,0.1677
23.4,1.7517,12.0335,0.1694
23.6,1.7667,12.2229,0.1714
23.8,1.7816,12.4105,0.1749
24,1.7967,12.6007,0.1763
24.2,1.8115,12.7876,0.1785
24.4,1.8267,12.9803,0.1805
24.6,1.8416,13.1678,0.1836
24.8,1.8567,13.3637,0.1859
25,1.8716,13.5545,0.1881
25.2,1.8868,13.7478,0.1901
25.4,1.9015,13.9367,0.1932
25.6,1.9167,14.1339,0.1959
25.8,1.9316,14.3231,0.1978
26,1.9466,14.5187,0.2001
26.2,1.9616,14.7119,0.2033
26.4,1.9768,14.9096,0.2058
26.6,1.9916,15.101,0.2081
26.8,2.0068,15.2991,0.2105
27,2.0216,15.49,0.2144
27.2,2.0367,15.6867,0.2165
27.4,2.0515,15.8797,0.2185
27.6,2.0667,16.0774,0.2218
27.8,2.0816,16.2708,0.2242
28,2.0968,16.4699,0.2269
28.2,2.1116,16.6597,0.2295
28.4,2.1267,16.857,0.2321
28.6,2.1416,17.0498,0.2346
28.8,2.1567,17.2469,0.2375
29,2.1715,17.4373,0.2403
29.2,2.1867,17.6365,0.2422
29.4,2.2017,17.8281,0.2454
29.6,2.2167,18.0247,0.2484
29.8,2.2316,18.2142,0.2509
30,2.2467,18.4084,0.2538
30.2,2.2615,18.5953,0.2569
30.4,2.2767,18.7914,0.2607
30.6,2.2916,18.9748,0.2628
30.8,2.3067,19.1676,0.2658
31,2.3217,19.3524,0.2693
31.2,2.3367,19.5396,0.2731
31.4,2.3515,19.7184,0.2759
31.6,2.3667,19.9053,0.2793
31.8,2.3816,20.0783,0.2835
32,2.3966,20.2591,0.2872
32.2,2.4116,20.4304,0.291
32.4,2.4268,20.6038,0.295
32.6,2.4416,20.7663,0.2998
32.8,2.4567,20.9284,0.3048
33,2.4715,21.0775,0.3092
33.2,2.4866,21.2302,0.3147
33.4,2.5016,21.3708,0.3211
33.6,2.5167,21.5078,0.3265
33.8,2.5316,21.631,0.333
34,2.5468,21.751,0.34
34.2,2.5617,21.8536,0.348
34.4,2.5767,21.952,0.3566
34.6,2.5916,22.034,0.3659
34.8,2.6067,22.1128,0.3773
35,2.6216,22.1795,0.3903
35.2,2.6367,22.2407,0.4039
35.4,2.6517,22.2863,0.4194
35.6,2.6668,22.3343,0.4367
35.8,2.6817,22.3678,0.4561
36,2.6967,22.398,0.4756
36.2,2.7116,22.4216,0.4958
36.4,2.7267,22.4428,0.5171
36.6,2.7417,22.46,0.5385
36.8,2.7567,22.4782,0.5575
37,2.7718,22.4887,0.5754
37.2,2.7868,22.499,0.5939
37.4,2.8017,22.5104,0.6128
37.6,2.8167,22.518,0.6307
37.8,2.8316,22.5243,0.6491
38,2.8467,22.5343,0.6676
38.2,2.8618,22.5434,0.6869
38.4,2.8767,22.5502,0.7051
38.6,2.8917,22.5596,0.7237
38.8,2.9068,22.568,0.7427
39,2.9218,22.5744,0.7627
39.2,2.9366,22.5827,0.7819
39.4,2.9518,22.5914,0.8007
39.6,2.9667,22.5973,0.8201
39.8,2.9818,22.6103,0.841
40,2.9967,22.6166,0.8599
40.2,3.0117,22.6263,0.8796
40.4,3.0267,22.6352,0.8993
40.6,3.0418,22.6451,0.92
40.8,3.0566,22.6495,0.94
41,3.0718,22.661,0.9598
41.2,3.0868,22.6683,0.9806
41.4,3.1018,22.6797,1.0012
41.6,3.1166,22.6866,1.0216
41.8,3.1318,22.697,1.0417
42,3.1467,22.7027,1.0631
42.2,3.1618,22.7142,1.0841
42.4,3.1767,22.7195,1.1046
42.6,3.1917,22.7288,1.1257
42.8,3.2067,22.7383,1.1471
43,3.2219,22.7476,1.1686
43.2,3.2366,22.7521,1.1888
43.4,3.2517,22.7639,1.21
43.6,3.2667,22.7683,1.2318
43.8,3.2817,22.7789,1.2533
44,3.2966,22.7837,1.2742
44.2,3.3118,22.7945,1.2954
44.4,3.3267,22.8011,1.3175
44.6,3.3418,22.8131,1.339
44.8,3.3567,22.8151,1.3595
45,3.3717,22.8261,1.3807
45.2,3.3867,22.8318,1.4034
45.4,3.4018,22.8414,1.4244
45.6,3.4166,22.8463,1.4448
45.8,3.4318,22.8588,1.4667
46,3.4468,22.8639,1.4885
46.2,3.4618,22.8739,1.5092
46.4,3.4766,22.8781,1.5296
46.6,3.4918,22.8892,1.5508
46.8,3.5066,22.8931,1.5723
47,3.5218,22.9061,1.5925
47.2,3.5367,22.9082,1.6131
47.4,3.5517,22.9206,1.6345
47.6,3.5667,22.9281,1.6552
47.8,3.5817,22.9367,1.6753
48,3.5966,22.9411,1.6958
48.2,3.6118,22.9534,1.7183
48.4,3.6267,22.956,1.7393
48.6,3.6417,22.9677,1.7599
48.8,3.6567,22.9737,1.7805
49,3.6718,22.9829,1.8019
49.2,3.6867,22.9901,1.8221
49.4,3.7018,22.9997,1.8412
49.6,3.7166,22.9997,1.8616
49.8,3.7316,23.0123,1.882
50,3.7467,23.0191,1.9019
50.2,3.7617,23.0264,1.9214
50.4,3.7766,23.0336,1.9415
50.6,3.7917,23.043,1.9622
50.8,3.8068,23.049,1.9831
51,3.8216,23.0564,2.0049
51.2,3.8367,23.0617,2.0257
51.4,3.8517,23.0692,2.0446
51.6,3.8668,23.0777,2.0638
51.8,3.8818,23.0847,2.0826
52,3.8968,23.0897,2.1033
52.2,3.9116,23.0967,2.1219
52.4,3.9268,23.1065,2.1411
52.6,3.9417,23.1086,2.1607
52.8,3.9566,23.1153,2.18
53,3.9717,23.122,2.1998
53.2,3.9868,23.1306,2.2199
53.4,4.0016,23.1344,2.2402
53.6,4.0168,23.1425,2.2619
53.8,4.0317,23.1474,2.2815
54,4.0468,23.1552,2.302
54.2,4.0616,23.1578,2.3214
54.4,4.0767,23.1652,2.3416
54.6,4.0916,23.1697,2.361
54.8,4.1068,23.1812,2.3814
55,4.1217,23.1819,2.4016
55.2,4.1368,23.1908,2.421
55.4,4.1518,23.1934,2.4409
55.6,4.1668,23.2008,2.4606
55.8,4.1816,23.2016,2.4806
56,4.1968,23.2105,2.5002
56.2,4.2117,23.213,2.5202
56.4,4.2268,23.2234,2.5408
56.6,4.2417,23.2247,2.5613
56.8,4.2568,23.2303,2.5806
57,4.2716,23.2335,2.5998
57.2,4.2868,23.2422,2.6208
57.4,4.3016,23.2404,2.6405
57.6,4.3167,23.2512,2.66
57.8,4.3317,23.2532,2.6804
58,4.3468,23.2623,2.7008
58.2,4.3616,23.2617,2.72
58.4,4.3768,23.2688,2.7395
58.6,4.3916,23.2692,2.7602
58.8,4.4068,23.2796,2.7811
59,4.4216,23.2767,2.801
59.2,4.4368,23.2849,2.8216
59.4,4.4516,23.2876,2.8421
59.6,4.4668,23.296,2.8635
59.8,4.4816,23.2939,2.8835
60,4.4967,23.3015,2.9045
60.2,4.5117,23.3014,2.9254
60.4,4.5268,23.3094,2.9469
60.6,4.5416,23.3072,2.9664
60.8,4.5568,23.317,2.9872
61,4.5717,23.3173,3.0098
61.2,4.5868,23.3261,3.0317
61.4,4.6016,23.3223,3.0526
61.6,4.6167,23.3288,3.0741
61.8,4.6316,23.3292,3.0951
62,4.6468,23.3375,3.1158
62.2,4.6616,23.334,3.137
62.4,4.6768,23.3438,3.1591
62.6,4.6918,23.3436,3.18
62.8,4.7067,23.3486,3.2002
63,4.7216,23.3466,3.2213
63.2,4.7368,23.3535,3.2431
63.4,4.7516,23.3522,3.2648
63.6,4.7667,23.3594,3.2853
63.8,4.7817,23.3583,3.3065
64,4.7967,23.3642,3.3276
64.2,4.8117,23.3657,3.3483
64.4,4.8268,23.3712,3.369
64.6,4.8416,23.3661,3.3911
64.8,4.8567,23.3712,3.4126
65,4.8718,23.3712,3.4337
65.2,4.8866,23.3726,3.4544
65.4,4.9017,23.3751,3.4764
65.6,4.9168,23.3818,3.4976
65.8,4.9316,23.3824,3.5184
66,4.9467,23.3877,3.5394
66.2,4.9617,23.3862,3.5619
66.4,4.9766,23.3886,3.5823
66.6,4.9917,23.3927,3.6031
66.8,5.0067,23.3953,3.6241
67,5.0217,23.3957,3.6466
67.2,5.0367,23.3986,3.6673
67.4,5.0518,23.4014,3.6885
67.6,5.0665,23.4008,3.7112
67.8,5.0817,23.4025,3.7334
68,5.0967,23.4036,3.7551
68.2,5.1118,23.4074,3.7769
68.4,5.1266,23.4069,3.7985
68.6,5.1419,23.4119,3.8202
68.8,5.1567,23.4103,3.8408
69,5.1718,23.4143,3.8633
69.2,5.1866,23.4114,3.8841
69.4,5.2017,23.414,3.9057
69.6,5.2166,23.4149,3.9266
69.8,5.2319,23.4198,3.9484
70,5.2466,23.4171,3.9686
70.2,5.2618,23.4219,3.9901
70.4,5.2767,23.4189,4.0111
70.6,5.2917,23.4235,4.0318
70.8,5.3066,23.421,4.0522
71,5.3218,23.4245,4.0744
71.2,5.3366,23.4236,4.0957
71.4,5.3519,23.4305,4.1163
71.6,5.3667,23.4257,4.1371
71.8,5.3818,23.4298,4.1592
72,5.3966,23.4261,4.1794
72.2,5.4118,23.431,4.2006
72.4,5.4265,23.4271,4.2211
72.6,5.4418,23.4322,4.2433
72.8,5.4567,23.4294,4.2641
73,5.4718,23.4348,4.2839
73.2,5.4866,23.431,4.3057
73.4,5.5018,23.4345,4.3272
73.6,5.5166,23.4304,4.3475
73.8,5.5318,23.437,4.3688
74,5.5465,23.4312,4.3908
74.2,5.5618,23.4376,4.4112
74.4,5.5767,23.4345,4.4329
74.6,5.5918,23.4385,4.4542
74.8,5.6065,23.4333,4.4755
75,5.6218,23.4385,4.4964
75.2,5.6366,23.4342,4.5181
75.4,5.6518,23.4396,4.5402
75.6,5.6666,23.433,4.5604
75.8,5.6818,23.4388,4.5822
76,5.6966,23.4366,4.6037
76.2,5.7118,23.442,4.6261
76.4,5.7266,23.4344,4.6472
76.6,5.7417,23.4388,4.6692
76.8,5.7566,23.4355,4.6912
77,5.7718,23.441,4.7134
77.2,5.7865,23.4335,4.735
77.4,5.8018,23.4415,4.7572
77.6,5.8167,23.4364,4.7795
77.8,5.8317,23.4402,4.8017
78,5.8466,23.4351,4.8237
78.2,5.8618,23.4376,4.8461
78.4,5.8766,23.4345,4.8687
78.6,5.8918,23.4408,4.8907
78.8,5.9067,23.4353,4.9139
79,5.9217,23.4382,4.9359
79.2,5.9367,23.4362,4.9583
79.4,5.9517,23.4375,4.9805
79.6,5.9665,23.432,5.0034
79.8,5.9817,23.4373,5.0263
80,5.9967,23.4342,5.0482
80.2,6.0117,23.437,5.0705
80.4,6.0267,23.4337,5.0939
80.6,6.0418,23.4365,5.1163
80.8,6.0567,23.4344,5.1383
81,6.0717,23.4347,5.161
81.2,6.0866,23.4311,5.1838
81.4,6.1017,23.4329,5.2062
81.6,6.1167,23.4321,5.2294
81.8,6.1318,23.4324,5.2519
82,6.1466,23.4303,5.2744
82.2,6.1617,23.4322,5.298
82.4,6.1768,23.4309,5.3212
82.6,6.1916,23.4292,5.3447
82.8,6.2067,23.4282,5.3666
83,6.2217,23.4272,5.3896
83.2,6.2368,23.4295,5.4126
83.4,6.2517,23.4272,5.4351
83.6,6.2668,23.4272,5.4574
83.8,6.2817,23.4267,5.4799
84,6.2968,23.4263,5.5034
84.2,6.3116,23.422,5.5248
84.4,6.3267,23.4235,5.5478
84.6,6.3417,23.4218,5.5707
84.8,6.3569,23.4234,5.5938
85,6.3717,23.4205,5.6159
85.2,6.3868,23.4217,5.6391
85.4,6.4017,23.4178,5.6623
85.6,6.4168,23.4208,5.6841
85.8,6.4317,23.4161,5.7074
86,6.4468,23.4156,5.731
86.2,6.4617,23.4146,5.7539
86.4,6.4768,23.4172,5.7767
86.6,6.4916,23.4129,5.7992
86.8,6.5067,23.4146,5.8234
87,6.5217,23.4113,5.8463
87.2,6.5368,23.4116,5.8694
87.4,6.5516,23.4086,5.8937
87.6,6.5668,23.4093,5.9174
87.8,6.5818,23.4063,5.9406
88,6.5968,23.4094,5.9641
88.2,6.6116,23.4024,5.9889
88.4,6.6267,23.4051,6.0125
88.6,6.6417,23.4017,6.0356
88.8,6.6568,23.4028,6.06
89,6.6716,23.3961,6.0836
89.2,6.6867,23.4004,6.1081
89.4,6.7018,23.3989,6.1317
89.6,6.7168,23.3986,6.1565
89.8,6.7316,23.394,6.1806
90,6.7468,23.3959,6.2042
90.2,6.7617,23.3901,6.2288
90.4,6.7768,23.3928,6.2539
90.6,6.7917,23.3877,6.2786
90.8,6.8067,23.3892,6.3023
91,6.8217,23.3875,6.3281
91.2,6.8369,23.3883,6.3534
91.4,6.8516,23.3807,6.3775
91.6,6.8667,23.3833,6.4023
91.8,6.8817,23.3802,6.4285
92,6.8967,23.3799,6.4527
92.2,6.9116,23.3752,6.4776
92.4,6.9268,23.3785,6.5032
92.6,6.9417,23.3741,6.5292
92.8,6.9567,23.3759,6.5541
93,6.9716,23.3697,6.5798
93.2,6.9866,23.3704,6.6063
93.4,7.0016,23.367,6.6322
93.6,7.0167,23.3682,6.657
93.8,7.0316,23.3638,6.6822
94,7.0468,23.3655,6.7079
94.2,7.0618,23.3621,6.732
94.4,7.0767,23.3619,6.7562
94.6,7.0917,23.3568,6.7822
94.8,7.1067,23.356,6.8058
95,7.1217,23.3542,6.8303
95.2,7.1367,23.3549,6.856
95.4,7.1517,23.3496,6.8814
95.6,7.1667,23.3511,6.9059
95.8,7.1817,23.3494,6.9311
96,7.1967,23.3459,6.9569
96.2,7.2116,23.3425,6.9808
96.4,7.2267,23.3428,7.005
96.6,7.2418,23.3414,7.0314
96.8,7.2567,23.339,7.0561
97,7.2717,23.3377,7.0824
97.2,7.2868,23.3354,7.1088
97.4,7.3018,23.3347,7.1348
97.6,7.3167,23.3295,7.1602
97.8,7.3317,23.3273,7.1851
98,7.3466,23.3247,7.212
98.2,7.3618,23.3277,7.2369
98.4,7.3767,23.3215,7.2619
98.6,7.3917,23.3222,7.288
98.8,7.4067,23.3183,7.3139
99,7.4218,23.3176,7.3383
99.2,7.4366,23.3117,7.3642
99.4,7.4518,23.3135,7.3905
99.6,7.4666,23.3067,7.4154
99.8,7.4818,23.3105,7.4405
100,7.4967,23.3058,7.4668
100.2,7.5118,23.3053,7.4928
100.4,7.5266,23.2986,7.5177
100.6,7.5418,23.302,7.5438
100.8,7.5566,23.2917,7.5702
101,7.5717,23.2946,7.5954
101.2,7.5867,23.29,7.6213
101.4,7.6018,23.2915,7.6476
101.6,7.6166,23.2858,7.6731
101.8,7.6319,23.2875,7.6987
102,7.6467,23.2785,7.7249
102.2,7.6617,23.2816,7.751
102.4,7.6766,23.2739,7.7763
102.6,7.6917,23.2746,7.8026
102.8,7.7066,23.2711,7.83
103,7.7219,23.2736,7.8555
103.2,7.7367,23.2639,7.8817
103.4,7.7517,23.264,7.9089
103.6,7.7666,23.2602,7.9355
103.8,7.7818,23.2607,7.9624
104,7.7966,23.2516,7.9897
104.2,7.8118,23.2545,8.0175
104.4,7.8267,23.2484,8.0436
104.6,7.8418,23.2502,8.0707
104.8,7.8567,23.2427,8.0984
105,7.8717,23.2414,8.125
105.2,7.8866,23.2366,8.1509
105.4,7.9018,23.2376,8.1785
105.6,7.9166,23.2289,8.2062
105.8,7.9317,23.2312,8.2323
106,7.9467,23.2261,8.26
106.2,7.9618,23.2266,8.2872
106.4,7.9766,23.2177,8.3137
106.6,7.9917,23.2179,8.3407
106.8,8.0067,23.2106,8.3682
107,8.0217,23.2121,8.3945
107.2,8.0366,23.2051,8.4211
107.4,8.0518,23.2056,8.4488
107.6,8.0667,23.1998,8.476
107.8,8.0818,23.2,8.5023
108,8.0966,23.1905,8.5294
108.2,8.1117,23.19,8.5577
108.4,8.1267,23.1846,8.5845
108.6,8.1416,23.1832,8.6115
108.8,8.1566,23.1786,8.6399
109,8.1718,23.1781,8.6672
109.2,8.1867,23.1723,8.6939
109.4,8.2017,23.1716,8.7217
109.6,8.2166,23.1624,8.7502
109.8,8.2316,23.1594,8.7772
110,8.2467,23.1581,8.8049
110.2,8.2617,23.1543,8.8331
110.4,8.2767,23.1478,8.8606
110.6,8.2917,23.1476,8.8879
110.8,8.3068,23.143,8.9169
111,8.3216,23.1366,8.9449
111.2,8.3367,23.133,8.9723
111.4,8.3517,23.1281,9.0007
111.6,8.3667,23.1248,9.0294
111.8,8.3817,23.1222,9.0571
112,8.3968,23.1168,9.0858
112.2,8.4116,23.1115,9.1155
112.4,8.4268,23.1107,9.1442
112.6,8.4417,23.1037,9.1731
112.8,8.4567,23.0971,9.2031
113,8.4716,23.0937,9.2326
113.2,8.4868,23.0921,9.2618
113.4,8.5016,23.0841,9.2908
113.6,8.5168,23.0828,9.3209
113.8,8.5317,23.0756,9.3496
114,8.5467,23.0718,9.3785
114.2,8.5616,23.0646,9.4085
114.4,8.5768,23.0615,9.4375
114.6,8.5916,23.0528,9.4664
114.8,8.6068,23.0545,9.4966
115,8.6217,23.0454,9.5255
115.2,8.6367,23.0409,9.5543
115.4,8.6517,23.0356,9.5829
115.6,8.6668,23.0325,9.613
115.8,8.6815,23.0202,9.641
116,8.6968,23.0206,9.6699
116.2,8.7117,23.0128,9.7002
116.4,8.7268,23.01,9.7291
116.6,8.7416,23.0013,9.7575
116.8,8.7569,22.9987,9.788
117,8.7716,22.9877,9.8168
117.2,8.7868,22.9869,9.8456
117.4,8.8016,22.9749,9.8755
117.6,8.8168,22.9724,9.905
117.8,8.8317,22.9653,9.9343
118,8.8469,22.9632,9.9639
118.2,8.8616,22.9504,9.9938
118.4,8.8768,22.949,10.0231
118.6,8.8917,22.9386,10.0524
118.8,8.9067,22.9347,10.0837
119,8.9215,22.9248,10.1138
119.2,8.9368,22.9223,10.1449
119.4,8.9517,22.9121,10.1765
119.6,8.9668,22.9103,10.2068
119.8,8.9816,22.8973,10.2369
120,8.9968,22.8933,10.2685
120.2,9.0116,22.8823,10.2988
120.4,9.0268,22.8778,10.3284
120.6,9.0415,22.8664,10.359
120.8,9.0568,22.865,10.3896
121,9.0717,22.8533,10.4188
121.2,9.0868,22.8494,10.4495
121.4,9.1016,22.8361,10.48
121.6,9.1168,22.8317,10.5092
121.8,9.1316,22.8196,10.5393
122,9.1467,22.8173,10.5706
122.2,9.1616,22.8037,10.6002
122.4,9.1768,22.8006,10.6308
122.6,9.1917,22.7907,10.6619
122.8,9.2068,22.784,10.6922
123,9.2215,22.7687,10.7214
123.2,9.2368,22.7651,10.7534
123.4,9.2517,22.7519,10.7833
123.6,9.2667,22.7475,10.8138
123.8,9.2817,22.7347,10.8451
124,9.2968,22.7283,10.8757
124.2,9.3117,22.7173,10.9058
124.4,9.3268,22.7107,10.9372
124.6,9.3416,22.6951,10.9683
124.8,9.3567,22.6889,10.9978
125,9.3717,22.679,11.0293
125.2,9.3867,22.6706,11.0602
125.4,9.4016,22.658,11.09
125.6,9.4168,22.6523,11.1214
125.8,9.4317,22.639,11.1527
126,9.4466,22.6285,11.1828
126.2,9.4617,22.6174,11.2138
126.4,9.4768,22.6069,11.2455
126.6,9.4917,22.5961,11.2755
126.8,9.5068,22.5875,11.306
127,9.5217,22.5732,11.337
127.2,9.5367,22.5644,11.3675
127.4,9.5518,22.5539,11.398
127.6,9.5667,22.5387,11.4294
127.8,9.5816,22.5274,11.4595
128,9.5967,22.5171,11.4897
128.2,9.6118,22.5071,11.5209
128.4,9.6267,22.4943,11.5516
128.6,9.6417,22.4824,11.5818
128.8,9.6567,22.4695,11.6119
129,9.6718,22.4591,11.6438
129.2,9.6867,22.4435,11.6741
129.4,9.7017,22.4305,11.7039
129.6,9.7166,22.4177,11.736
129.8,9.7319,22.4096,11.7665
130,9.7467,22.3913,11.7966
130.2,9.7617,22.3821,11.8276
130.4,9.7767,22.3673,11.8584
130.6,9.7919,22.3546,11.8887
130.8,9.8066,22.3369,11.9198
131,9.8217,22.3263,11.9505
131.2,9.8367,22.3106,11.9807
131.4,9.8518,22.301,12.0121
131.6,9.8667,22.2827,12.0435
131.8,9.8818,22.2708,12.0736
132,9.8966,22.2541,12.1048
132.2,9.9119,22.2424,12.1364
132.4,9.9266,22.2225,12.1663
132.6,9.9417,22.2106,12.1967
132.8,9.9567,22.1946,12.2288
133,9.9719,22.1821,12.2589
133.2,9.9866,22.1622,12.2889
133.4,10.0018,22.15,12.3207
133.6,10.0167,22.1305,12.3517
133.8,10.0318,22.1182,12.3818
134,10.0466,22.0978,12.4127
134.2,10.0617,22.0837,12.4442
134.4,10.0767,22.0682,12.4741
134.6,10.0919,22.0548,12.505
134.8,10.1067,22.0322,12.5367
135,10.1217,22.018,12.5667
135.2,10.1367,21.9982,12.5973
135.4,10.1518,21.9823,12.6287
135.6,10.1666,21.963,12.6588
135.8,10.1818,21.9477,12.6897
136,10.1967,21.9276,12.7211
136.2,10.2118,21.9141,12.7515
136.4,10.2267,21.89,12.7825
136.6,10.2416,21.871,12.8138
136.8,10.2566,21.8542,12.844
137,10.2718,21.8369,12.8746
137.2,10.2866,21.8126,12.9064
137.4,10.3018,21.7989,12.9371
137.6,10.3168,21.7784,12.9675
137.8,10.3318,21.7593,12.9995
138,10.3466,21.7357,13.0306
138.2,10.3617,21.7176,13.061
138.4,10.3766,21.6963,13.0927
138.6,10.3917,21.6783,13.1241
138.8,10.4067,21.6546,13.155
139,10.4217,21.635,13.1866
139.2,10.4367,21.6151,13.2179
139.4,10.4518,21.5927,13.2488
139.6,10.4666,21.5668,13.2801
139.8,10.4817,21.5476,13.3112
140,10.4968,21.5252,13.3419
140.2,10.5117,21.5027,13.3731
140.4,10.5267,21.4799,13.4048
140.6,10.5418,21.4587,13.4356
140.8,10.5567,21.4346,13.4672
141,10.5717,21.4111,13.4993
141.2,10.5867,21.3854,13.5298
141.4,10.6016,21.3606,13.5606
141.6,10.6167,21.34,13.5931
141.8,10.6318,21.3142,13.6243
142,10.6467,21.2887,13.6545
142.2,10.6617,21.2642,13.6871
142.4,10.6769,21.2408,13.7177
142.6,10.6916,21.211,13.7488
142.8,10.7067,21.1869,13.7814
143,10.7217,21.1585,13.8118
143.2,10.7368,21.1362,13.8428
143.4,10.7517,21.1083,13.8757
143.6,10.7669,21.081,13.9065
143.8,10.7816,21.0501,13.9376
144,10.7967,21.0267,13.9697
144.2,10.8117,20.9953,14.0016
144.4,10.8267,20.9671,14.0324
144.6,10.8416,20.9376,14.0644
144.8,10.8569,20.914,14.0959
145,10.8717,20.8806,14.1271
145.2,10.8868,20.8531,14.1599
145.4,10.9017,20.8183,14.1918
145.6,10.9168,20.7922,14.2232
145.8,10.9316,20.757,14.2556
146,10.9468,20.7276,14.2878
146.2,10.9616,20.6945,14.3192
146.4,10.9768,20.6684,14.352
146.6,10.9917,20.6306,14.3842
146.8,11.0068,20.6002,14.4154
147,11.0217,20.5643,14.4483
147.2,11.0368,20.534,14.481
147.4,11.0516,20.4947,14.5118
147.6,11.0668,20.4642,14.5446
147.8,11.0817,20.4263,14.5776
148,11.0968,20.397,14.609
148.2,11.1117,20.3574,14.6412
148.4,11.1268,20.3216,14.675
148.6,11.1416,20.2821,14.7065
148.8,11.1568,20.2494,14.7386
149,11.1717,20.2051,14.7714
149.2,11.1867,20.1721,14.8031
149.4,11.2017,20.1324,14.8363
149.6,11.2168,20.0957,14.8693
149.8,11.2316,20.051,14.9007
150,11.2468,20.014,14.9335
150.2,11.2617,19.9688,14.9667
150.4,11.2767,19.9313,14.9981
150.6,11.2916,19.8862,15.0311
150.8,11.3068,19.8472,15.0644
151,11.3217,19.8023,15.0967
151.2,11.3368,19.7626,15.1293
151.4,11.3516,19.712,15.1632
151.6,11.3666,19.67,15.195
151.8,11.3817,19.6212,15.228
152,11.3967,19.5781,15.2616
152.2,11.4116,19.528,15.2939
152.4,11.4269,19.4834,15.3269
152.6,11.4418,19.4314,15.3611
152.8,11.4567,19.3865,15.3924
153,11.4717,19.3311,15.4263
153.2,11.4867,19.282,15.46
153.4,11.5016,19.2285,15.4926
153.6,11.5168,19.1791,15.5261
153.8,11.5317,19.1214,15.5607
154,11.5467,19.0715,15.5935
154.2,11.5618,19.0148,15.6268
154.4,11.5767,18.9586,15.6614
154.6,11.5916,18.8976,15.6946
154.8,11.6067,18.8404,15.7283
155,11.6217,18.7797,15.763
155.2,11.6367,18.7221,15.7958
155.4,11.6517,18.6569,15.8299
155.6,11.6668,18.5967,15.8648
155.8,11.6817,18.5314,15.898
156,11.6967,18.4666,15.9318
156.2,11.7117,18.3954,15.967
156.4,11.7266,18.328,16.0005
156.6,11.7418,18.26,16.0346
156.8,11.7567,18.1892,16.0698
157,11.7717,18.1162,16.1042
157.2,11.7868,18.0419,16.1382
157.4,11.8018,17.9654,16.1743
157.6,11.8166,17.8864,16.2089
157.8,11.8317,17.8052,16.2437
158,11.8467,17.7227,16.2801
158.2,11.8618,17.6403,16.3153
158.4,11.8767,17.5522,16.3506
158.6,11.8918,17.464,16.3873
158.8,11.9067,17.3718,16.4227
159,11.9218,17.2783,16.4573
159.2,11.9366,17.1764,16.4955
159.4,11.9518,17.0743,16.5327
159.6,11.9668,16.9476,16.5691
159.654,11.971,16.5602,16.6018
159.656,11.9711,16.1332,16.6452
159.658,11.9713,15.542,16.7021
159.66,11.9715,14.8227,16.7549
159.662,11.9716,13.9982,16.8127
159.664,11.9718,13.102,16.8778
159.666,11.9721,12.1669,16.9414
159.668,11.9724,11.2118,16.9997
159.67,11.9727,10.2496,17.0587
159.672,11.973,9.2941,17.1161
159.674,11.9734,8.3582,17.1648
159.676,11.9738,7.4523,17.2001
159.678,11.9742,6.5848,17.2266
159.68,11.9747,5.762,17.2494
159.682,11.9751,4.989,17.2676
159.684,11.9756,4.2714,17.2804
159.686,11.976,3.6104,17.2877
159.688,11.9765,3.0041,17.2905
159.69,11.9769,2.4515,17.2929
159.691,11.9771,2.1952,17.2945